Workbook

Sheet Summary
B1: Home Depot (NYSE: HD)
B2: Summary Income Statement & Supporting Financials
B5: Period End: | C5: =DATE(2021,1,31) -> 44227 | D5: =DATE(2022,1,30) -> 44591 | E5: =DATE(2022,1,29) -> 44590 | F5: =DATE(2024,1,28) -> 45319
B6: USD millions (expect per share data) | C6: FY2021A | D6: FY2022A | E6: FY2023A | F6: FY2024A | G6: FY2025E | H6: FY2026E | I6: FY2027E | J6: FY2028E | K6: FY2029E | L6: FY2030E | M6: FY2031E
C9: Historical | G9: Projections
B10: Income Statement
B11: Revenue | C11: 132110 | D11: 151157 | E11: 157403 | F11: 152669 | G11: ='Annual Model'!G10 -> 154195.69 | H11: ='Annual Model'!H10 -> 158821.56 | I11: ='Annual Model'!I10 -> 165174.42 | J11: ='Annual Model'!J10 -> 172276.92 | K11: ='Annual Model'!K10 -> 179168 | L11: ='Annual Model'!L10 -> 185886.8 | M11: ='Annual Model'!M10 -> 192392.84
B12: Growth % | D12: =D11/C11-1 -> 0.14417531 | E12: =E11/D11-1 -> 0.041321275 | F12: =F11/E11-1 -> -0.030075666 | G12: =G11/F11-1 -> 0.01 | H12: =H11/G11-1 -> 0.03 | I12: =I11/H11-1 -> 0.04 | J12: =J11/I11-1 -> 0.043 | K12: =K11/J11-1 -> 0.04 | ... M12: =M11/L11-1 -> 0.035
B13: COGS | C13: ='Annual Model'!C11 -> 87257 | D13: ='Annual Model'!D11 -> 100325 | E13: ='Annual Model'!E11 -> 104625 | F13: ='Annual Model'!F11 -> 101709 | G13: ='Annual Model'!G11 -> 102848.53 | H13: ='Annual Model'!H11 -> 106092.8 | I13: ='Annual Model'!I11 -> 110501.69 | J13: ='Annual Model'!J11 -> 115425.54 | ... M13: ='Annual Model'!M11 -> 129480.38
B14: COGS % Rev | D14: =D13/D11 -> 0.66371389 | E14: =E13/E11 -> 0.66469508 | F14: =F13/F11 -> 0.66620598 | G14: =G13/G11 -> 0.667 | H14: =H13/H11 -> 0.668 | I14: =I13/I11 -> 0.669 | J14: =J13/J11 -> 0.67 | K14: =K13/K11 -> 0.671 | ... M14: =M13/M11 -> 0.673
B15: COGS Growth % | G15: =G14/F14-1 -> 0.0011918611 | H15: =H14/G14-1 -> 0.0014992504 | I15: =I14/H14-1 -> 0.001497006 | J15: =J14/I14-1 -> 0.0014947683 | K15: =K14/J14-1 -> 0.0014925373 | L15: =L14/K14-1 -> 0.001490313 | M15: =M14/L14-1 -> 0.0014880952
B16: Gross Profit | C16: ='Annual Model'!C12 -> 44853 | D16: ='Annual Model'!D12 -> 50832 | E16: ='Annual Model'!E12 -> 52778 | F16: ='Annual Model'!F12 -> 50960 | G16: ='Annual Model'!G12 -> 51347.165 | H16: ='Annual Model'!H12 -> 52728.758 | I16: ='Annual Model'!I12 -> 54672.734 | J16: ='Annual Model'!J12 -> 56851.385 | ... M16: ='Annual Model'!M12 -> 62912.458
B17: Gross Margin % | D17: ='Annual Model'!D12/'Annual Model'!D10 -> 0.33628611 | E17: ='Annual Model'!E12/'Annual Model'!E10 -> 0.33530492 | F17: ='Annual Model'!F12/'Annual Model'!F10 -> 0.33379402 | G17: ='Annual Model'!G12/'Annual Model'!G10 -> 0.333 | H17: ='Annual Model'!H12/'Annual Model'!H10 -> 0.332 | I17: ='Annual Model'!I12/'Annual Model'!I10 -> 0.331 | J17: ='Annual Model'!J12/'Annual Model'!J10 -> 0.33 | K17: ='Annual Model'!K12/'Annual Model'!K10 -> 0.329 | ... M17: ='Annual Model'!M12/'Annual Model'!M10 -> 0.327
B18: EBITDA | C18: ='Annual Model'!C15 -> 20406 | D18: ='Annual Model'!D15 -> 25426 | E18: ='Annual Model'!E15 -> 26494 | F18: ='Annual Model'!F15 -> 24362 | G18: ='Annual Model'!G15 -> 24581.389 | H18: ='Annual Model'!H15 -> 25160.009 | I18: ='Annual Model'!I15 -> 26001.235 | J18: ='Annual Model'!J15 -> 26947.011 | ... M18: ='Annual Model'!M15 -> 29516.3
B19: YoY Growth % | D19: =D18/C18-1 -> 0.24600608 | E19: =E18/D18-1 -> 0.042004248 | F19: =F18/E18-1 -> -0.08047105 | G19: =G18/F18-1 -> 0.0090053669 | H19: =H18/G18-1 -> 0.023538951 | I19: =I18/H18-1 -> 0.033435041 | J19: =J18/I18-1 -> 0.036374279 | K19: =K18/J18-1 -> 0.033351099 | ... M19: =M18/L18-1 -> 0.028297363
B20: EBITDA Margin % | D20: ='Annual Model'!D15/'Annual Model'!D10 -> 0.16820921 | E20: ='Annual Model'!E15/'Annual Model'!E10 -> 0.16831954 | F20: ='Annual Model'!F15/'Annual Model'!F10 -> 0.15957398 | G20: ='Annual Model'!G15/'Annual Model'!G10 -> 0.15941683 | H20: ='Annual Model'!H15/'Annual Model'!H10 -> 0.15841683 | I20: ='Annual Model'!I15/'Annual Model'!I10 -> 0.15741683 | J20: ='Annual Model'!J15/'Annual Model'!J10 -> 0.15641683 | K20: ='Annual Model'!K15/'Annual Model'!K10 -> 0.15541683 | ... M20: ='Annual Model'!M15/'Annual Model'!M10 -> 0.15341683
B21: EBIT | C21: ='Annual Model'!C17 -> 18278 | D21: ='Annual Model'!D17 -> 23040 | E21: ='Annual Model'!E17 -> 24039 | F21: ='Annual Model'!F17 -> 21689 | G21: ='Annual Model'!G17 -> 22075.783 | H21: ='Annual Model'!H17 -> 22579.235 | I21: ='Annual Model'!I17 -> 23317.23 | J21: ='Annual Model'!J17 -> 24147.594 | ... M21: ='Annual Model'!M17 -> 26390.009
B22: Operating Margin % | C22: =C21/C11 -> 0.1383544 | D22: =D21/D11 -> 0.1524243 | E22: =E21/E11 -> 0.15272263 | F22: =F21/F11 -> 0.14206551 | G22: =G21/G11 -> 0.14316732 | H22: =H21/H11 -> 0.14216732 | I22: =I21/I11 -> 0.14116732 | J22: =J21/J11 -> 0.14016732 | ... M22: =M21/M11 -> 0.13716732
B23: Growth Rate % | D23: =D21/C21-1 -> 0.26053179 | E23: =E21/D21-1 -> 0.043359375 | F23: =F21/E21-1 -> -0.09775781 | G23: =G21/F21-1 -> 0.017833141 | H23: =H21/G21-1 -> 0.022805621 | I23: =I21/H21-1 -> 0.032684676 | J23: =J21/I21-1 -> 0.035611604 | K23: =K21/J21-1 -> 0.032580296 | ... M23: =M21/L21-1 -> 0.027509082
B24: EBT | C24: ='Annual Model'!C22 -> 16978 | D24: ='Annual Model'!D22 -> 21737 | E24: ='Annual Model'!E22 -> 22477 | F24: ='Annual Model'!F22 -> 19924 | G24: ='Annual Model'!G22 -> 20001.935 | H24: ='Annual Model'!H22 -> 20620.25 | I24: ='Annual Model'!I22 -> 21489.355 | J24: ='Annual Model'!J22 -> 22451.436 | ... M24: ='Annual Model'!M22 -> 25104.254
B25: EBT Margin % | D25: ='Annual Model'!D22/'Annual Model'!D10 -> 0.14380412 | E25: ='Annual Model'!E22/'Annual Model'!E10 -> 0.14279906 | F25: ='Annual Model'!F22/'Annual Model'!F10 -> 0.13050456 | G25: ='Annual Model'!G22/'Annual Model'!G10 -> 0.12971786 | H25: ='Annual Model'!H22/'Annual Model'!H10 -> 0.12983281 | I25: ='Annual Model'!I22/'Annual Model'!I10 -> 0.13010098 | J25: ='Annual Model'!J22/'Annual Model'!J10 -> 0.13032179 | K25: ='Annual Model'!K22/'Annual Model'!K10 -> 0.1304255 | ... M25: ='Annual Model'!M22/'Annual Model'!M10 -> 0.13048435
B26: Net Earnings (Income) | C26: ='Annual Model'!C25 -> 12866 | D26: ='Annual Model'!D25 -> 16433 | E26: ='Annual Model'!E25 -> 17105 | F26: ='Annual Model'!F25 -> 15143 | G26: ='Annual Model'!G25 -> 15201.47 | H26: ='Annual Model'!H25 -> 15671.39 | I26: ='Annual Model'!I25 -> 16331.91 | J26: ='Annual Model'!J25 -> 17063.092 | ... M26: ='Annual Model'!M25 -> 19079.233
B27: Growth % | D27: =Summary!D26/Summary!C26-1 -> 0.27724234 | E27: =Summary!E26/Summary!D26-1 -> 0.040893324 | F27: =Summary!F26/Summary!E26-1 -> -0.1147033 | G27: =Summary!G26/Summary!F26-1 -> 0.0038612196 | H27: =Summary!H26/Summary!G26-1 -> 0.030912779 | I27: =Summary!I26/Summary!H26-1 -> 0.04214811 | J27: =Summary!J26/Summary!I26-1 -> 0.044770148 | K27: =Summary!K26/Summary!J26-1 -> 0.040827685 | ... M27: =Summary!M26/Summary!L26-1 -> 0.035062897

Sheet Assumptions
B1: Home Depot (NYSE: HD)
B2: Assumptions/Drivers
B5: Period End: | C5: =DATE(2021,1,31) -> 44227 | D5: =DATE(2022,1,30) -> 44591 | E5: =DATE(2022,1,29) -> 44590 | F5: =DATE(2024,1,28) -> 45319
B6: USD millions (expect per share data) | C6: FY2021A | D6: FY2022A | E6: FY2023A | F6: FY2024A | G6: FY2025E | H6: FY2026E | I6: FY2027E | J6: FY2028E | K6: FY2029E | L6: FY2030E | M6: FY2031E
B9: Income Statement
B10: Revenue growth % YoY | D10: ='Annual Model'!D10/'Annual Model'!C10-1 -> 0.14417531 | E10: ='Annual Model'!E10/'Annual Model'!D10-1 -> 0.041321275 | F10: ='Annual Model'!F10/'Annual Model'!E10-1 -> -0.030075666 | G10: 0.01 | H10: 0.03 | I10: 0.04 | J10: 0.043 | K10: 0.04 | L10: 0.0375 | M10: 0.035
B11: COGS % Rev | C11: ='Annual Model'!C11/'Annual Model'!C10 -> 0.66048747 | D11: ='Annual Model'!D11/'Annual Model'!D10 -> 0.66371389 | E11: ='Annual Model'!E11/'Annual Model'!E10 -> 0.66469508 | F11: ='Annual Model'!F11/'Annual Model'!F10 -> 0.66620598 | G11: 0.667 | H11: 0.668 | I11: 0.669 | J11: 0.67 | K11: 0.671 | L11: 0.672 | M11: 0.673
B12: SG&A % Rev | C12: ='Annual Model'!C14/'Annual Model'!C10 -> 0.18505034 | D12: ='Annual Model'!D14/'Annual Model'!D10 -> 0.1680769 | E12: ='Annual Model'!E14/'Annual Model'!E10 -> 0.16698538 | F12: ='Annual Model'!F14/'Annual Model'!F10 -> 0.17422004 | G12: =AVERAGE(C12:F12) -> 0.17358317 | H12: =G12 -> 0.17358317 | I12: =H12 -> 0.17358317 | J12: =I12 -> 0.17358317 | K12: =J12 -> 0.17358317 | L12: =K12 -> 0.17358317 | M12: =L12 -> 0.17358317
B13: Depreciation % Rev | C13: ='Annual Model'!C16/'Annual Model'!C10 -> 0.016107789 | D13: ='Annual Model'!D16/'Annual Model'!D10 -> 0.015784912 | E13: ='Annual Model'!E16/'Annual Model'!E10 -> 0.015596907 | F13: ='Annual Model'!F16/'Annual Model'!F10 -> 0.017508466 | G13: =AVERAGE(C13:F13) -> 0.016249519 | H13: =G13 -> 0.016249519 | I13: =H13 -> 0.016249519 | J13: =I13 -> 0.016249519 | K13: =J13 -> 0.016249519 | L13: =K13 -> 0.016249519 | M13: =L13 -> 0.016249519
B14: Income Tax Expense | C14: ='Annual Model'!C24 -> 0.24219578 | D14: ='Annual Model'!D24 -> 0.24400791 | E14: ='Annual Model'!E24 -> 0.23899987 | F14: ='Annual Model'!F24 -> 0.23996186 | G14: 0.24 | H14: 0.24 | I14: 0.24 | J14: 0.24 | K14: 0.24 | L14: 0.24 | M14: 0.24
B15: Basic Weighted Average Common Shares | C15: ='Annual Model'!C30 -> 1074 | D15: ='Annual Model'!D30 -> 1054 | E15: ='Annual Model'!E30 -> 1022 | F15: ='Annual Model'!F30 -> 999 | G15: 995 | H15: 992 | I15: 990 | J15: 988 | K15: 986 | L15: 986 | M15: 984
B16: Share Growth % | D16: =D15/C15-1 -> -0.018621974 | E16: =E15/D15-1 -> -0.030360531 | F16: =F15/E15-1 -> -0.022504892 | G16: =G15/F15-1 -> -0.004004004 | H16: =H15/G15-1 -> -0.0030150754 | I16: =I15/H15-1 -> -0.002016129 | J16: =J15/I15-1 -> -0.002020202 | K16: =K15/J15-1 -> -0.0020242915 | ... M16: =M15/L15-1 -> -0.0020283976
B17: Diluted Weighted Average Common Shares | C17: ='Annual Model'!C31 -> 1078 | D17: ='Annual Model'!D31 -> 1058 | E17: ='Annual Model'!E31 -> 1025 | F17: ='Annual Model'!F31 -> 1002 | G17: 997 | H17: 995 | I17: 992 | J17: 990 | K17: 988 | L17: 988 | M17: 986
B18: Share Growth % | D18: =D17/C17-1 -> -0.018552876 | E18: =E17/D17-1 -> -0.031190926 | F18: =F17/E17-1 -> -0.022439024 | G18: =G17/F17-1 -> -0.00499002 | H18: =H17/G17-1 -> -0.0020060181 | I18: =I17/H17-1 -> -0.0030150754 | J18: =J17/I17-1 -> -0.002016129 | K18: =K17/J17-1 -> -0.002020202 | ... M18: =M17/L17-1 -> -0.0020242915
B20: Balance Sheet
B21: Other Current Assets: | C21: ='Annual Model'!C41 -> 1040 | D21: ='Annual Model'!D41 -> 963 | E21: ='Annual Model'!E41 -> 1218 | F21: ='Annual Model'!F41 -> 1511 | G21: 1511 | H21: 1511 | I21: 1511 | J21: 1511 | K21: 1511 | L21: 1511 | M21: 1511
B22: Operating Lease ROU Assets | C22: ='Annual Model'!C45 -> 5595 | D22: ='Annual Model'!D45 -> 5962 | E22: ='Annual Model'!E45 -> 5968 | F22: ='Annual Model'!F45 -> 6941 | G22: 6941 | H22: 6941 | I22: 6941 | J22: 6941 | K22: 6941 | L22: 6941 | M22: 6941
B23: Goodwill | C23: ='Annual Model'!C46 -> 2254 | D23: ='Annual Model'!D46 -> 7126 | E23: ='Annual Model'!E46 -> 7449 | F23: ='Annual Model'!F46 -> 7444 | G23: 7444 | H23: 7444 | I23: 7444 | J23: 7444 | K23: 7444 | L23: 7444 | M23: 7444
B25: Cash Flow Statement
B26: CAPEX % Rev | C26: =-'Annual Model'!C108/'Annual Model'!C10 -> 0.018643555 | D26: =-'Annual Model'!D108/'Annual Model'!D10 -> 0.016975727 | E26: =-'Annual Model'!E108/'Annual Model'!E10 -> 0.019815378 | F26: =-'Annual Model'!F108/'Annual Model'!F10 -> 0.021130681 | G26: 0.02 | H26: 0.02 | I26: 0.02 | J26: 0.02 | K26: 0.02 | L26: 0.02 | M26: 0.02
B27: Intangible Asset Amortization: | C27: ='Annual Model'!C89 -> 0 | D27: ='Annual Model'!D89 -> 0 | E27: ='Annual Model'!E89 -> 0 | F27: ='Annual Model'!F89 -> 0 | G27: 0 | H27: 0 | I27: 0 | J27: 0 | K27: 0 | L27: 0 | M27: 0
B28: Stock-Based Compensation Expense: | C28: ='Annual Model'!C90 -> 310 | D28: ='Annual Model'!D90 -> 399 | E28: ='Annual Model'!E90 -> 366 | F28: ='Annual Model'!F90 -> 380 | G28: =G29*'Annual Model'!G10 -> 385.48923 | H28: =H29*'Annual Model'!H10 -> 397.0539 | I28: =I29*'Annual Model'!I10 -> 412.93606 | J28: =J29*'Annual Model'!J10 -> 430.69231 | K28: =K29*'Annual Model'!K10 -> 447.92 | L28: =L29*'Annual Model'!L10 -> 464.717 | M28: =M29*'Annual Model'!M10 -> 480.9821
B29: SBC % Rev | C29: ='Annual Model'!C90/'Annual Model'!C10 -> 0.0023465294 | D29: ='Annual Model'!D90/'Annual Model'!D10 -> 0.0026396396 | E29: ='Annual Model'!E90/'Annual Model'!E10 -> 0.0023252416 | F29: ='Annual Model'!F90/'Annual Model'!F10 -> 0.0024890449 | G29: 0.0025 | H29: 0.0025 | I29: 0.0025 | J29: 0.0025 | K29: 0.0025 | L29: 0.0025 | M29: 0.0025
B30: Impairment Loss: | C30: ='Annual Model'!C91 -> 0 | D30: ='Annual Model'!D91 -> 0 | E30: ='Annual Model'!E91 -> 0 | F30: ='Annual Model'!F91 -> 0 | G30: 0 | H30: 0 | I30: 0 | J30: 0 | K30: 0 | L30: 0 | M30: 0
B31: Changes in Other Current Assets: | C31: ='Annual Model'!C94 -> 43 | D31: ='Annual Model'!D94 -> -330 | E31: ='Annual Model'!E94 -> -311 | F31: ='Annual Model'!F94 -> -184 | G31: -184 | H31: -184 | I31: -184 | J31: -184 | K31: -184 | L31: -184 | M31: -184
B32: Changes in Deferred Revenue: | C32: ='Annual Model'!C92 -> 702 | D32: ='Annual Model'!D92 -> 775 | E32: ='Annual Model'!E92 -> -526 | F32: ='Annual Model'!F92 -> -318 | G32: =G33*'Annual Model'!G10 -> 231.29354 | H32: =H33*'Annual Model'!H10 -> 238.23234 | I32: =I33*'Annual Model'!I10 -> 247.76163 | J32: =J33*'Annual Model'!J10 -> 258.41538 | K32: =K33*'Annual Model'!K10 -> 268.752 | L32: =L33*'Annual Model'!L10 -> 278.8302 | M32: =M33*'Annual Model'!M10 -> 288.58926
B33: DR % Rev | C33: ='Annual Model'!C92/'Annual Model'!C10 -> 0.0053137537 | D33: ='Annual Model'!D92/'Annual Model'!D10 -> 0.0051271195 | E33: ='Annual Model'!E92/'Annual Model'!E10 -> -0.0033417406 | F33: ='Annual Model'!F92/'Annual Model'!F10 -> -0.0020829376 | G33: 0.0015 | H33: 0.0015 | I33: 0.0015 | J33: 0.0015 | K33: 0.0015 | L33: 0.0015 | M33: 0.0015
B34: Other Operating Activities: | C34: ='Annual Model'!C95 -> 121 | D34: ='Annual Model'!D95 -> 196 | E34: ='Annual Model'!E95 -> 271 | F34: ='Annual Model'!F95 -> 314 | G34: =G35*'Annual Model'!G10 -> 354.65009 | H34: =H35*'Annual Model'!H10 -> 397.0539 | I34: =I35*'Annual Model'!I10 -> 445.97094 | J34: =J35*'Annual Model'!J10 -> 499.60308 | K34: =K35*'Annual Model'!K10 -> 555.4208 | L34: =L35*'Annual Model'!L10 -> 613.42644 | M34: =M35*'Annual Model'!M10 -> 673.37493
B35: Other Operating Activities % Rev | C35: ='Annual Model'!C95/'Annual Model'!C10 -> 0.00091590341 | D35: ='Annual Model'!D95/'Annual Model'!D10 -> 0.0012966651 | E35: ='Annual Model'!E95/'Annual Model'!E10 -> 0.0017216953 | F35: ='Annual Model'!F95/'Annual Model'!F10 -> 0.0020567371 | G35: 0.0023 | H35: 0.0025 | I35: 0.0027 | J35: 0.0029 | K35: 0.0031 | L35: 0.0033 | M35: 0.0035
B37: Payments for Businesses Acquired: | C37: ='Annual Model'!C109 -> -7780 | D37: ='Annual Model'!D109 -> -421 | E37: ='Annual Model'!E109 -> 0 | F37: ='Annual Model'!F109 -> -1514 | G37: 0 | H37: 0 | I37: 0 | J37: 0 | K37: 0 | L37: 0 | M37: 0
B38: Proceeds from Sales of Property and Equipment: | C38: ='Annual Model'!C110 -> 0 | D38: ='Annual Model'!D110 -> 0 | E38: ='Annual Model'!E110 -> 0 | F38: ='Annual Model'!F110 -> 0 | G38: 0 | H38: 0 | I38: 0 | J38: 0 | K38: 0 | L38: 0 | M38: 0
B39: Other Investing Activities: | C39: ='Annual Model'!C111 -> 73 | D39: ='Annual Model'!D111 -> 18 | E39: ='Annual Model'!E111 -> -21 | F39: ='Annual Model'!F111 -> 11 | G39: 10 | H39: 10 | I39: 10 | J39: 10 | K39: 10 | L39: 10 | M39: 10
B41: Repurchases of Common Stock: | C41: ='Annual Model'!C122 -> -791 | D41: ='Annual Model'!D122 -> -14809 | E41: ='Annual Model'!E122 -> -6696 | F41: ='Annual Model'!F122 -> -7951 | G41: -3500 | H41: -3500 | I41: -3500 | J41: -3500 | K41: -3500 | L41: -3500 | M41: -3500
B42: Proceeds from Sales of Common Stock: | C42: ='Annual Model'!C123 -> 326 | D42: ='Annual Model'!D123 -> 337 | E42: ='Annual Model'!E123 -> 264 | F42: ='Annual Model'!F123 -> 323 | G42: =AVERAGE(C42:F42) -> 312.5 | H42: =G42 -> 312.5 | I42: =H42 -> 312.5 | J42: =I42 -> 312.5 | K42: =J42 -> 312.5 | L42: =K42 -> 312.5 | M42: =L42 -> 312.5
B43: Cash Dividends: | C43: ='Annual Model'!C124 -> -6451 | D43: ='Annual Model'!D124 -> -6985 | E43: ='Annual Model'!E124 -> -7789 | F43: ='Annual Model'!F124 -> -8383 | G43: =-G44*'Annual Model'!G30 -> -8955 | H43: =-H44*'Annual Model'!H30 -> -9076.8 | I43: =-I44*'Annual Model'!I30 -> -9207 | J43: =-J44*'Annual Model'!J30 -> -9336.6 | K43: =-K44*'Annual Model'!K30 -> -9367 | L43: =-L44*'Annual Model'!L30 -> -9416.3 | M43: =-M44*'Annual Model'!M30 -> -9446.4
B44: Price per Share | C44: =-C43/'Annual Model'!C30 -> 6.0065177 | D44: =-D43/'Annual Model'!D30 -> 6.6271347 | E44: =-E43/'Annual Model'!E30 -> 7.6213307 | F44: =-F43/'Annual Model'!F30 -> 8.3913914 | G44: 9 | H44: 9.15 | I44: 9.3 | J44: 9.45 | K44: 9.5 | L44: 9.55 | M44: 9.6
B45: Dividend Increase % | D45: =D44/C44-1 -> 0.10332393 | E45: =E44/D44-1 -> 0.15001898 | F45: =F44/E44-1 -> 0.10104019 | G45: =G44/F44-1 -> 0.072527735 | H45: =H44/G44-1 -> 0.016666667 | I45: =I44/H44-1 -> 0.016393443 | J45: =J44/I44-1 -> 0.016129032 | K45: =K44/J44-1 -> 0.0052910053 | ... M45: =M44/L44-1 -> 0.0052356021
B46: Other Financing Activities: | C46: ='Annual Model'!C125 -> -154 | D46: ='Annual Model'!D125 -> -145 | E46: ='Annual Model'!E125 -> -188 | F46: ='Annual Model'!F125 -> -156 | G46: -156 | H46: -156 | I46: -156 | J46: -156 | K46: -156 | L46: -156 | M46: -156
B48: Effect of Exchange Rate Changes on Cash & Cash Equivalents: | C48: ='Annual Model'!C129 -> 76 | D48: ='Annual Model'!D129 -> -34 | E48: ='Annual Model'!E129 -> -68 | F48: ='Annual Model'!F129 -> 3 | G48: 0 | H48: 0 | I48: 0 | J48: 0 | K48: 0 | L48: 0 | M48: 0

Sheet IS Scenario Analysis
B1: Home Depot (NYSE: HD)
B2: Scenario Analysis
C4: Historicals | G4: Projections
B5: Period End: | C5: =DATE(2021,1,31) -> 44227 | D5: =DATE(2022,1,30) -> 44591 | E5: =DATE(2022,1,29) -> 44590 | F5: =DATE(2024,1,28) -> 45319
B6: USD millions (expect per share data) | C6: FY2021A | D6: FY2022A | E6: FY2023A | F6: FY2024A | G6: FY2025E | H6: FY2026E | I6: FY2027E | J6: FY2028E | K6: FY2029E | L6: FY2030E | M6: FY2031E
B8: Scenario Selection | C8: 1
B13: Scenario
B14: Bull Case Scenario (2)
B15: Revenue Growth | G15: 0.02 | H15: 0.03 | I15: 0.04 | J15: 0.045 | K15: 0.045 | L15: 0.04 | M15: 0.04
B16: COGS % Rev | G16: 0.66 | H16: 0.6605 | I16: 0.661 | J16: 0.6615 | K16: 0.662 | L16: 0.6625 | M16: 0.663
B17: SG&A % Rev | G17: 0.171 | H17: 0.171 | I17: 0.171 | J17: 0.171 | K17: 0.171 | L17: 0.171 | M17: 0.171
B18: Depreciation % Rev | G18: 0.0155 | H18: 0.0155 | I18: 0.0155 | J18: 0.0155 | K18: 0.0155 | L18: 0.0155 | M18: 0.0155
B20: Base Case Scenario (1)
B21: Revenue Growth | G21: 0.01 | H21: 0.03 | I21: 0.034 | J21: 0.043 | K21: 0.0375 | L21: 0.0375 | M21: 0.035
B22: COGS % Rev | G22: 0.667 | H22: 0.6675 | I22: 0.668 | J22: 0.6685 | K22: 0.6685 | L22: 0.669 | M22: 0.6695
B23: SG&A % Rev | G23: 0.1736 | H23: 0.1736 | I23: 0.1736 | J23: 0.1736 | K23: 0.1736 | L23: 0.1736 | M23: 0.1736
B24: Depreciation % Rev | G24: 0.0162 | H24: 0.0162 | I24: 0.0162 | J24: 0.0162 | K24: 0.0162 | L24: 0.0162 | M24: 0.0162
B26: Bear Case Scenario (3)
B27: Revenue Growth | G27: 0.01 | H27: 0.02 | I27: 0.0275 | J27: 0.03 | K27: 0.035 | L27: 0.035 | M27: 0.037
B28: COGS % Rev | G28: 0.67 | H28: 0.6705 | I28: 0.671 | J28: 0.6715 | K28: 0.672 | L28: 0.6725 | M28: 0.673
B29: SG&A % Rev | G29: 0.175 | H29: 0.175 | I29: 0.175 | J29: 0.175 | K29: 0.175 | L29: 0.175 | M29: 0.175
B30: Depreciation % Rev | G30: 0.017 | H30: 0.017 | I30: 0.017 | J30: 0.017 | K30: 0.017 | L30: 0.017 | M30: 0.017
B34: Income Statement
B35: Revenue | C35: 132110 | D35: 151157 | E35: 157403 | F35: 152669 | G35: =F35*(1+CHOOSE($C$8,G21,G15,G27)) -> 154195.69 | H35: =G35*(1+CHOOSE($C$8,H21,H15,H27)) -> 158821.56 | I35: =H35*(1+CHOOSE($C$8,I21,I15,I27)) -> 164221.49 | J35: =I35*(1+CHOOSE($C$8,J21,J15,J27)) -> 171283.02 | K35: =J35*(1+CHOOSE($C$8,K21,K15,K27)) -> 177706.13 | L35: =K35*(1+CHOOSE($C$8,L21,L15,L27)) -> 184370.11 | M35: =L35*(1+CHOOSE($C$8,M21,M15,M27)) -> 190823.06
B36: Cost of Sales | C36: 87257 | D36: 100325 | E36: 104625 | F36: 101709 | G36: =G35*CHOOSE($C$8,G22,G16,G28) -> 102848.53 | H36: =H35*CHOOSE($C$8,H22,H16,H28) -> 106013.39 | I36: =I35*CHOOSE($C$8,I22,I16,I28) -> 109699.96 | J36: =J35*CHOOSE($C$8,J22,J16,J28) -> 114502.7 | K36: =K35*CHOOSE($C$8,K22,K16,K28) -> 118796.55 | L36: =L35*CHOOSE($C$8,L22,L16,L28) -> 123343.6 | M36: =M35*CHOOSE($C$8,M22,M16,M28) -> 127756.04
B37: Gross Profit | C37: =C35-C36 -> 44853 | D37: =D35-D36 -> 50832 | E37: =E35-E36 -> 52778 | F37: =F35-F36 -> 50960 | G37: =G35-G36 -> 51347.165 | H37: =H35-H36 -> 52808.169 | I37: =I35-I36 -> 54521.536 | J37: =J35-J36 -> 56780.32 | ... M37: =M35-M36 -> 63067.023
B38: Operating Expenses
B39: Selling, General, and Administrative: | C39: 24447 | D39: 25406 | E39: 26284 | F39: 26598 | G39: =G35*CHOOSE($C$8,G23,G17,G29) -> 26768.372 | H39: =H35*CHOOSE($C$8,H23,H17,H29) -> 27571.423 | I39: =I35*CHOOSE($C$8,I23,I17,I29) -> 28508.851 | J39: =J35*CHOOSE($C$8,J23,J17,J29) -> 29734.732 | K39: =K35*CHOOSE($C$8,K23,K17,K29) -> 30849.784 | L39: =L35*CHOOSE($C$8,L23,L17,L29) -> 32006.651 | M39: =M35*CHOOSE($C$8,M23,M17,M29) -> 33126.884
B40: EBITDA | C40: =C42+C41 -> 20406 | D40: =D42+D41 -> 25426 | E40: =E42+E41 -> 26494 | F40: =F42+F41 -> 24362 | G40: =G42+G41 -> 24578.793 | H40: =H42+H41 -> 25236.746 | I40: =I42+I41 -> 26012.685 | J40: =J42+J41 -> 27045.589 | ... M40: =M42+M41 -> 29940.139
B41: Depreciation and Amortization | C41: 2128 | D41: 2386 | E41: 2455 | F41: 2673 | G41: =G35*CHOOSE($C$8,G24,G18,G30) -> 2497.9702 | H41: =H35*CHOOSE($C$8,H24,H18,H30) -> 2572.9093 | I41: =I35*CHOOSE($C$8,I24,I18,I30) -> 2660.3882 | J41: =J35*CHOOSE($C$8,J24,J18,J30) -> 2774.7849 | K41: =K35*CHOOSE($C$8,K24,K18,K30) -> 2878.8393 | L41: =L35*CHOOSE($C$8,L24,L18,L30) -> 2986.7958 | M41: =M35*CHOOSE($C$8,M24,M18,M30) -> 3091.3337
B42: EBIT | C42: =C37-C39-C41 -> 18278 | D42: =D37-D39-D41 -> 23040 | E42: =E37-E39-E41 -> 24039 | F42: =F37-F39-F41 -> 21689 | G42: =G37-G39-G41 -> 22080.823 | H42: =H37-H39-H41 -> 22663.837 | I42: =I37-I39-I41 -> 23352.296 | J42: =J37-J39-J41 -> 24270.804 | ... M42: =M37-M39-M41 -> 26848.805
B43: Interest & Other (Income) Expense
B44: Interest and Investment Income: | C44: -47 | D44: -44 | E44: -55 | F44: -178 | G44: =-'Annual Model'!G274 -> -58.881795 | H44: =-'Annual Model'!H274 -> -100.59525 | I44: =-'Annual Model'!I274 -> -121.50485 | J44: =-'Annual Model'!J274 -> -147.77248 | K44: =-'Annual Model'!K274 -> -182.6769 | L44: =-'Annual Model'!L274 -> -224.2935 | M44: =-'Annual Model'!M274 -> -273.17456
B45: Interest Expense: | C45: 1347 | D45: 1347 | E45: 1617 | F45: 1943 | G45: ='Annual Model'!G272 -> 2132.73 | H45: ='Annual Model'!H272 -> 2059.58 | I45: ='Annual Model'!I272 -> 1949.38 | J45: ='Annual Model'!J272 -> 1843.93 | K45: ='Annual Model'!K272 -> 1748.93 | L45: ='Annual Model'!L272 -> 1653.93 | M45: ='Annual Model'!M272 -> 1558.93
B46: Net Interest & Other | C46: =SUM(C44:C45) -> 1300 | D46: =SUM(D44:D45) -> 1303 | E46: =SUM(E44:E45) -> 1562 | F46: =SUM(F44:F45) -> 1765 | G46: =SUM(G44:G45) -> 2073.8482 | H46: =SUM(H44:H45) -> 1958.9848 | I46: =SUM(I44:I45) -> 1827.8752 | J46: =SUM(J44:J45) -> 1696.1575 | ... M46: =SUM(M44:M45) -> 1285.7554
B47: EBT | C47: =C42-C46 -> 16978 | D47: =D42-D46 -> 21737 | E47: =E42-E46 -> 22477 | F47: =F42-F46 -> 19924 | G47: =G42-G46 -> 20006.975 | H47: =H42-H46 -> 20704.852 | I47: =I42-I46 -> 21524.421 | J47: =J42-J46 -> 22574.646 | ... M47: =M42-M46 -> 25563.05
B48: Provision for Income Taxes | C48: 4112 | D48: 5304 | E48: 5372 | F48: 4781 | G48: ='Annual Model'!G23 -> 4800.4644 | H48: ='Annual Model'!H23 -> 4948.86 | I48: ='Annual Model'!I23 -> 5157.4451 | J48: ='Annual Model'!J23 -> 5388.3447 | K48: ='Annual Model'!K23 -> 5608.3384 | L48: ='Annual Model'!L23 -> 5820.9225 | M48: ='Annual Model'!M23 -> 6025.0209
B49: Income Tax Expense (%): | C49: =C48/C47 -> 0.24219578 | D49: =D48/D47 -> 0.24400791 | E49: =E48/E47 -> 0.23899987 | F49: =F48/F47 -> 0.23996186 | G49: ='Annual Model'!G24 -> 0.24 | H49: ='Annual Model'!H24 -> 0.24 | I49: ='Annual Model'!I24 -> 0.24 | J49: ='Annual Model'!J24 -> 0.24 | K49: ='Annual Model'!K24 -> 0.24 | L49: ='Annual Model'!L24 -> 0.24 | M49: ='Annual Model'!M24 -> 0.24
B50: Net Earnings (Net Income) | C50: =C47-C48 -> 12866 | D50: =D47-D48 -> 16433 | E50: =E47-E48 -> 17105 | F50: =F47-F48 -> 15143 | G50: =G47-G48 -> 15206.51 | H50: =H47-H48 -> 15755.992 | I50: =I47-I48 -> 16366.976 | J50: =J47-J48 -> 17186.301 | ... M50: =M47-M48 -> 19538.029
B51: Earnings Per Share
...

Sheet Annual Model
B1: Home Depot (NYSE: HD)
B2: Annual Financial Model
B3: Financial Statements & Supporting Schedules
B5: Period End: | C5: =DATE(2021,1,31) -> 44227 | D5: =DATE(2022,1,30) -> 44591 | E5: =DATE(2022,1,29) -> 44590 | F5: =DATE(2024,1,28) -> 45319
B6: USD millions (expect per share data) | C6: FY2021A | D6: FY2022A | E6: FY2023A | F6: FY2024A | G6: FY2025E | H6: FY2026E | I6: FY2027E | J6: FY2028E | K6: FY2029E | L6: FY2030E | M6: FY2031E
C8: Historical | G8: Projections
B9: Income Statement
B10: Revenue | C10: 132110 | D10: 151157 | E10: 157403 | F10: 152669 | G10: =F10*(1+Assumptions!G10) -> 154195.69 | H10: =G10*(1+Assumptions!H10) -> 158821.56 | I10: =H10*(1+Assumptions!I10) -> 165174.42 | J10: =I10*(1+Assumptions!J10) -> 172276.92 | K10: =J10*(1+Assumptions!K10) -> 179168 | L10: =K10*(1+Assumptions!L10) -> 185886.8 | M10: =L10*(1+Assumptions!M10) -> 192392.84
B11: Cost of Sales | C11: 87257 | D11: 100325 | E11: 104625 | F11: 101709 | G11: =G10*Assumptions!G11 -> 102848.53 | H11: =H10*Assumptions!H11 -> 106092.8 | I11: =I10*Assumptions!I11 -> 110501.69 | J11: =J10*Assumptions!J11 -> 115425.54 | K11: =K10*Assumptions!K11 -> 120221.73 | L11: =L10*Assumptions!L11 -> 124915.93 | M11: =M10*Assumptions!M11 -> 129480.38
B12: Gross Profit | C12: =C10-C11 -> 44853 | D12: =D10-D11 -> 50832 | E12: =E10-E11 -> 52778 | F12: =F10-F11 -> 50960 | G12: =G10-G11 -> 51347.165 | H12: =H10-H11 -> 52728.758 | I12: =I10-I11 -> 54672.734 | J12: =J10-J11 -> 56851.385 | ... M12: =M10-M11 -> 62912.458
B13: Operating Expenses
B14: Selling, General, and Administrative: | C14: 24447 | D14: 25406 | E14: 26284 | F14: 26598 | G14: =G10*Assumptions!G12 -> 26765.776 | H14: =H10*Assumptions!H12 -> 27568.749 | I14: =I10*Assumptions!I12 -> 28671.499 | J14: =J10*Assumptions!J12 -> 29904.374 | K14: =K10*Assumptions!K12 -> 31100.549 | L14: =L10*Assumptions!L12 -> 32266.819 | M14: =M10*Assumptions!M12 -> 33396.158
B15: EBITDA | C15: =C17+C16 -> 20406 | D15: =D17+D16 -> 25426 | E15: =E17+E16 -> 26494 | F15: =F17+F16 -> 24362 | G15: =G17+G16 -> 24581.389 | H15: =H17+H16 -> 25160.009 | I15: =I17+I16 -> 26001.235 | J15: =J17+J16 -> 26947.011 | ... M15: =M17+M16 -> 29516.3
B16: Depreciation and Amortization | C16: 2128 | D16: 2386 | E16: 2455 | F16: 2673 | G16: =Assumptions!G13*'Annual Model'!G10 -> 2505.6057 | H16: =Assumptions!H13*'Annual Model'!H10 -> 2580.7739 | I16: =Assumptions!I13*'Annual Model'!I10 -> 2684.0049 | J16: =Assumptions!J13*'Annual Model'!J10 -> 2799.4171 | K16: =Assumptions!K13*'Annual Model'!K10 -> 2911.3938 | L16: =Assumptions!L13*'Annual Model'!L10 -> 3020.571 | M16: =Assumptions!M13*'Annual Model'!M10 -> 3126.291
B17: EBIT | C17: =C12-C14-C16 -> 18278 | D17: =D12-D14-D16 -> 23040 | E17: =E12-E14-E16 -> 24039 | F17: =F12-F14-F16 -> 21689 | G17: =G12-G14-G16 -> 22075.783 | H17: =H12-H14-H16 -> 22579.235 | I17: =I12-I14-I16 -> 23317.23 | J17: =J12-J14-J16 -> 24147.594 | ... M17: =M12-M14-M16 -> 26390.009
B18: Interest & Other (Income) Expense
B19: Interest and Investment Income: | C19: -47 | D19: -44 | E19: -55 | F19: -178 | G19: =-G274 -> -58.881795 | H19: =-H274 -> -100.59525 | I19: =-I274 -> -121.50485 | J19: =-J274 -> -147.77248 | K19: =-K274 -> -182.6769 | L19: =-L274 -> -224.2935 | M19: =-M274 -> -273.17456
B20: Interest Expense: | C20: 1347 | D20: 1347 | E20: 1617 | F20: 1943 | G20: =G272 -> 2132.73 | H20: =H272 -> 2059.58 | I20: =I272 -> 1949.38 | J20: =J272 -> 1843.93 | K20: =K272 -> 1748.93 | L20: =L272 -> 1653.93 | M20: =M272 -> 1558.93
B21: Net Interest & Other | C21: =SUM(C19:C20) -> 1300 | D21: =SUM(D19:D20) -> 1303 | E21: =SUM(E19:E20) -> 1562 | F21: =SUM(F19:F20) -> 1765 | G21: =SUM(G19:G20) -> 2073.8482 | H21: =SUM(H19:H20) -> 1958.9848 | I21: =SUM(I19:I20) -> 1827.8752 | J21: =SUM(J19:J20) -> 1696.1575 | ... M21: =SUM(M19:M20) -> 1285.7554
B22: EBT | C22: =C17-C21 -> 16978 | D22: =D17-D21 -> 21737 | E22: =E17-E21 -> 22477 | F22: =F17-F21 -> 19924 | G22: =G17-G21 -> 20001.935 | H22: =H17-H21 -> 20620.25 | I22: =I17-I21 -> 21489.355 | J22: =J17-J21 -> 22451.436 | ... M22: =M17-M21 -> 25104.254
B23: Provision for Income Taxes | C23: 4112 | D23: 5304 | E23: 5372 | F23: 4781 | G23: =G24*G22 -> 4800.4644 | H23: =H24*H22 -> 4948.86 | I23: =I24*I22 -> 5157.4451 | J23: =J24*J22 -> 5388.3447 | K23: =K24*K22 -> 5608.3384 | L23: =L24*L22 -> 5820.9225 | M23: =M24*M22 -> 6025.0209
B24: Income Tax Expense (%): | C24: =C23/C22 -> 0.24219578 | D24: =D23/D22 -> 0.24400791 | E24: =E23/E22 -> 0.23899987 | F24: =F23/F22 -> 0.23996186 | G24: =Assumptions!G14 -> 0.24 | H24: =Assumptions!H14 -> 0.24 | I24: =Assumptions!I14 -> 0.24 | J24: =Assumptions!J14 -> 0.24 | K24: =Assumptions!K14 -> 0.24 | L24: =Assumptions!L14 -> 0.24 | M24: =Assumptions!M14 -> 0.24
B25: Net Earnings (Net Income) | C25: =C22-C23 -> 12866 | D25: =D22-D23 -> 16433 | E25: =E22-E23 -> 17105 | F25: =F22-F23 -> 15143 | G25: =G22-G23 -> 15201.47 | H25: =H22-H23 -> 15671.39 | I25: =I22-I23 -> 16331.91 | J25: =J22-J23 -> 17063.092 | ... M25: =M22-M23 -> 19079.233
B26: Earnings Per Share
B27: Basic EPS | C27: 11.98 | D27: 15.59 | E27: 16.74 | F27: 15.16 | G27: =G25/G30 -> 15.27786 | H27: =H25/H30 -> 15.797772 | I27: =I25/I30 -> 16.496878 | J27: =J25/J30 -> 17.270336 | K27: =K25/K30 -> 18.011905 | L27: =L25/L30 -> 18.694646 | M27: =M25/M30 -> 19.389464
B28: Diluted EPS | C28: 11.94 | D28: 15.53 | E28: 16.69 | F28: 15.11 | G28: =G25/G31 -> 15.247212 | H28: =H25/H31 -> 15.750141 | I28: =I25/I31 -> 16.463619 | J28: =J25/J31 -> 17.235446 | K28: =K25/K31 -> 17.975443 | L28: =L25/L31 -> 18.656803 | M28: =M25/M31 -> 19.350135
B29: Shares Used in Computing EPS
B30: Basic Weighted Average Common Shares | C30: 1074 | D30: 1054 | E30: 1022 | F30: 999 | G30: =Assumptions!G15 -> 995 | H30: =Assumptions!H15 -> 992 | I30: =Assumptions!I15 -> 990 | J30: =Assumptions!J15 -> 988 | K30: =Assumptions!K15 -> 986 | L30: =Assumptions!L15 -> 986 | M30: =Assumptions!M15 -> 984
B31: Diluted Weighted Average Common Shares | C31: 1078 | D31: 1058 | E31: 1025 | F31: 1002 | G31: =Assumptions!G17 -> 997 | H31: =Assumptions!H17 -> 995 | I31: =Assumptions!I17 -> 992 | J31: =Assumptions!J17 -> 990 | K31: =Assumptions!K17 -> 988 | L31: =Assumptions!L17 -> 988 | M31: =Assumptions!M17 -> 986
B36: Balance Sheet
B37: Assets
B38: Cash & Cash Equivalents: | C38: 2133 | D38: 7895 | E38: 2343 | F38: 2757 | G38: =F38+G128 -> 7919.359 | H38: =G38+H128 -> 7249.6904 | I38: =H38+I128 -> 6301.2789 | J38: =I38+J128 -> 6953.2177 | K38: =J38+K128 -> 8282.163 | L38: =K38+L128 -> 10276.537 | M38: =L38+M128 -> 13058.375
B39: Receivables, Net: | C39: 2106 | D39: 2992 | E39: 3426 | F39: 3317 | G39: =F39-G97 -> 3404.9788 | H39: =G39-H97 -> 3507.1282 | I39: =H39-I97 -> 3647.4133 | J39: =I39-J97 -> 3804.2521 | K39: =J39-K97 -> 3956.4221 | L39: =K39-L97 -> 4104.788 | M39: =L39-M97 -> 4248.4556
B40: Merchandise Inventories: | C40: 14531 | D40: 16627 | E40: 22068 | F40: 24886 | G40: =F40-G98 -> 23740.031 | H40: =G40-H98 -> 24488.544 | I40: =H40-I98 -> 25506.212 | J40: =I40-J98 -> 26642.744 | K40: =J40-K98 -> 27749.81 | L40: =K40-L98 -> 28833.334 | M40: =L40-M98 -> 29886.91
B41: Other Current Assets: | C41: 1040 | D41: 963 | E41: 1218 | F41: 1511 | G41: =F41-G94-G123 -> 1382.5 | H41: =G41-H94-H123 -> 1254 | I41: =H41-I94-I123 -> 1125.5 | J41: =I41-J94-J123 -> 997 | K41: =J41-K94-K123 -> 868.5 | L41: =K41-L94-L123 -> 740 | M41: =L41-M94-M123 -> 611.5
B42: Total Current Assets | C42: =SUM(C38:C41) -> 19810 | D42: =SUM(D38:D41) -> 28477 | E42: =SUM(E38:E41) -> 29055 | F42: =SUM(F38:F41) -> 32471 | G42: =SUM(G38:G41) -> 36446.869 | H42: =SUM(H38:H41) -> 36499.363 | I42: =SUM(I38:I41) -> 36580.404 | J42: =SUM(J38:J41) -> 38397.214 | ... M42: =SUM(M38:M41) -> 47805.24
B44: Net Property & Equipment | C44: 22770 | D44: 24705 | E44: 25199 | F44: 25631 | G44: =F44-G108-G88-G109-G110 -> 25303.518 | H44: =G44-H108-H88-H109-H110 -> 24909.732 | I44: =H44-I108-I88-I109-I110 -> 24477.829 | J44: =I44-J108-J88-J109-J110 -> 24015.699 | K44: =J44-K108-K88-K109-K110 -> 23512.222 | L44: =K44-L108-L88-L109-L110 -> 22957.235 | M44: =L44-M108-M88-M109-M110 -> 22339.975
B45: Operating Lease ROU Assets | C45: 5595 | D45: 5962 | E45: 5968 | F45: 6941 | G45: =Assumptions!G22 -> 6941 | H45: =Assumptions!H22 -> 6941 | I45: =Assumptions!I22 -> 6941 | J45: =Assumptions!J22 -> 6941 | K45: =Assumptions!K22 -> 6941 | L45: =Assumptions!L22 -> 6941 | M45: =Assumptions!M22 -> 6941
B46: Goodwill | C46: 2254 | D46: 7126 | E46: 7449 | F46: 7444 | G46: =Assumptions!G23 -> 7444 | H46: =Assumptions!H23 -> 7444 | I46: =Assumptions!I23 -> 7444 | J46: =Assumptions!J23 -> 7444 | K46: =Assumptions!K23 -> 7444 | L46: =Assumptions!L23 -> 7444 | M46: =Assumptions!M23 -> 7444
B47: Intangible Assets: | C47: 0 | D47: 0 | E47: 0 | F47: 0 | G47: =F47-G89 -> 0 | H47: =G47-H89 -> 0 | I47: =H47-I89 -> 0 | J47: =I47-J89 -> 0 | K47: =J47-K89 -> 0 | L47: =K47-L89 -> 0 | M47: =L47-M89 -> 0
...

Sheet Quarterly Model
B3: Home Depot (NYSE: HD)
B4: Quarterly Financial Model
B5: Financial Statements & Supporting Schedules
B7: Period End: | C7: =DATE(2020,5,3) -> 43954 | D7: =DATE(2020,8,2) -> 44045 | E7: =DATE(2020,11,1) -> 44136 | F7: =DATE(2021,1,31) -> 44227 | G7: =DATE(2021,1,31) -> 44227 | H7: =DATE(2021,5,2) -> 44318 | I7: =DATE(2021,8,1) -> 44409 | J7: =DATE(2021,10,31) -> 44500 | K7: =DATE(2022,1,30) -> 44591 | L7: =DATE(2022,1,30) -> 44591 | M7: =DATE(2022,5,1) -> 44682 | N7: =DATE(2022,7,31) -> 44773 | O7: =DATE(2022,10,30) -> 44864 | P7: =DATE(2022,1,29) -> 44590 | Q7: =DATE(2022,1,29) -> 44590 | R7: =DATE(2023,4,30) -> 45046 | S7: =DATE(2023,7,30) -> 45137 | T7: =DATE(2023,10,29) -> 45228 | U7: =DATE(2024,1,28) -> 45319 | V7: =DATE(2024,1,28) -> 45319 | W7: =DATE(2024,4,28) -> 45410 | X7: =DATE(2024,7,28) -> 45501 | Y7: =DATE(2024,10,27) -> 45592
B8: USD millions (expect per share data) | C8: Q1-2020 | D8: Q2-2020 | E8: Q3-2020 | F8: Q4-2020 | G8: FY2020 | H8: Q1-2021 | I8: Q2-2021 | J8: Q3-2021 | K8: Q4-2021 | L8: FY2021 | M8: Q1-2022 | N8: Q2-2022 | O8: Q3-2022 | P8: Q4-2022 | Q8: FY2022 | R8: Q1-2023 | S8: Q2-2023 | T8: Q3-2023 | U8: Q4-2023 | V8: FY2023 | W8: Q1-2024 | X8: Q2-2024 | Y8: Q3-2024 | Z8: Q4-2024E | AA8: FY2024E | AB8: Q1-2025E | AC8: Q2-2025E | AD8: Q3-2025E | AE8: Q4-2025E | AF8: FY2025E | AG8: Q1-2026E | AH8: Q2-2026E | AI8: Q3-2026E | AJ8: Q4-2026E | AK8: FY2026E | AL8: FY2027E | AM8: FY2028E | AN8: FY2029E | AO8: FY2030E
B11: Income Statement
B12: Revenue | C12: 28260 | D12: 38053 | E12: 33536 | F12: =G12-C12-D12-E12 -> 32261 | G12: 132110 | H12: 37500 | I12: 41118 | J12: 36820 | K12: =L12-H12-I12-J12 -> 35719 | L12: 151157 | M12: 38908 | N12: 43792 | O12: 38872 | P12: =Q12-M12-N12-O12 -> 35831 | Q12: 157403 | R12: 37257 | S12: 42916 | T12: 37710 | U12: =V12-R12-S12-T12 -> 34786 | V12: 152669 | W12: 36418 | X12: 43175 | Y12: 40217
B13: y/y growth % | H13: =H12/C12-1 -> 0.32696391 | I13: =I12/D12-1 -> 0.080545555 | J13: =J12/E12-1 -> 0.097924618 | K13: =K12/F12-1 -> 0.10718825 | L13: =L12/G12-1 -> 0.14417531 | M13: =M12/H12-1 -> 0.037546667 | N13: =N12/I12-1 -> 0.065032346 | O13: =O12/J12-1 -> 0.055730581 | ... Y13: =Y12/T12-1 -> 0.06648104
B14: Cost of Sales | C14: 18635 | D14: 25112 | E14: 22080 | F14: =G14-C14-D14-E14 -> 21430 | G14: 87257 | H14: 24758 | I14: 27453 | J14: 24257 | K14: =L14-H14-I14-J14 -> 23857 | L14: 100325 | M14: 25763 | N14: 29309 | O14: 25648 | P14: =Q14-M14-N14-O14 -> 23905 | Q14: 104625 | R14: 24700 | S14: 28759 | T14: 24972 | U14: =V14-R14-S14-T14 -> 23278 | V14: 101709 | W14: 23985 | X14: 28759 | Y14: 26792
B15: COGS % Rev | G15: =G14/G12 -> 0.66048747 | H15: =H14/H12 -> 0.66021333 | I15: =I14/I12 -> 0.6676638 | J15: =J14/J12 -> 0.65879957 | K15: =K14/K12 -> 0.66790784 | L15: =L14/L12 -> 0.66371389 | M15: =M14/M12 -> 0.66215174 | N15: =N14/N12 -> 0.66927749 | ... Y15: =Y14/Y12 -> 0.66618594
B16: Gross Profit | C16: =C12-C14 -> 9625 | D16: =D12-D14 -> 12941 | E16: =E12-E14 -> 11456 | F16: =G16-C16-D16-E16 -> 10831 | G16: =G12-G14 -> 44853 | H16: =H12-H14 -> 12742 | I16: =I12-I14 -> 13665 | J16: =J12-J14 -> 12563 | K16: =L16-H16-I16-J16 -> 11862 | L16: =L12-L14 -> 50832 | M16: =M12-M14 -> 13145 | N16: =N12-N14 -> 14483 | O16: =O12-O14 -> 13224 | P16: =Q16-M16-N16-O16 -> 11926 | Q16: =Q12-Q14 -> 52778 | R16: =R12-R14 -> 12557 | S16: =S12-S14 -> 14157 | T16: =T12-T14 -> 12738 | U16: =U12-U14 -> 11508 | V16: =V12-V14 -> 50960 | W16: =W12-W14 -> 12433 | X16: =X12-X14 -> 14416 | Y16: =Y12-Y14 -> 13425
B17: Operating Expenses
B18: Selling, General, and Administrative: | C18: 5829 | D18: 6355 | E18: 6076 | F18: =G18-C18-D18-E18 -> 6187 | G18: 24447 | H18: 6374 | I18: 6433 | J18: 6168 | K18: =L18-H18-I18-J18 -> 6431 | L18: 25406 | M18: 6610 | N18: 6657 | O18: 6468 | P18: =Q18-M18-N18-O18 -> 6549 | Q18: 26284 | R18: 6355 | S18: 6915 | T18: 6649 | U18: =V18-R18-S18-T18 -> 6679 | V18: 26598 | W18: 6667 | X18: 7144 | Y18: 7212
B19: SG&A % Rev | G19: =G18/G12 -> 0.18505034 | L19: =L18/L12 -> 0.1680769 | Q19: =Q18/Q12 -> 0.16698538 | V19: =V18/V12 -> 0.17422004
B20: EBITDA | C20: =C23+C21 -> 3796 | D20: =D23+D21 -> 6586 | E20: =E23+E21 -> 5380 | F20: =F23+F21 -> 4644 | G20: =G23+G21 -> 20406 | H20: =H23+H21 -> 6368 | I20: =I23+I21 -> 7232 | J20: =J23+J21 -> 6395 | K20: =L20-H20-I20-J20 -> 5431 | L20: =L23+L21 -> 25426 | M20: =M23+M21 -> 6535 | N20: =N23+N21 -> 7826 | O20: =O23+O21 -> 6756 | P20: =P23+P21 -> 5377 | Q20: =Q23+Q21 -> 26494 | R20: =R23+R21 -> 6202 | S20: =S23+S21 -> 7242 | ... Y20: =Y23+Y21 -> 6213
B21: Depreciation and Amortization | C21: 520 | D21: 519 | E21: 528 | F21: =G21-C21-D21-E21 -> 561 | G21: 2128 | H21: 587 | I21: 593 | J21: 600 | K21: =L21-H21-I21-J21 -> 606 | L21: 2386 | M21: 606 | N21: 616 | O21: 608 | P21: =Q21-M21-N21-O21 -> 625 | Q21: 2455 | R21: 651 | S21: 653 | T21: 683 | U21: =V21-R21-S21-T21 -> 686 | V21: 2673 | W21: 687 | X21: 738 | Y21: 795
B22: Depreciation % Revenue: | C22: =C21/C12 -> 0.018400566 | D22: =D21/D12 -> 0.013638872 | E22: =E21/E12 -> 0.015744275 | F22: =F21/F12 -> 0.017389418 | G22: =G21/G12 -> 0.016107789 | H22: =H21/H12 -> 0.015653333 | I22: =I21/I12 -> 0.014421908 | J22: =J21/J12 -> 0.016295492 | ... Y22: =Y21/Y12 -> 0.01976776
B23: EBIT | C23: =C16-C18-C21 -> 3276 | D23: =D16-D18-D21 -> 6067 | E23: =E16-E18-E21 -> 4852 | F23: =F16-F18-F21 -> 4083 | G23: =G16-G18-G21 -> 18278 | H23: =H16-H18-H21 -> 5781 | I23: =I16-I18-I21 -> 6639 | J23: =J16-J18-J21 -> 5795 | K23: =L23-H23-I23-J23 -> 4825 | L23: =L16-L18-L21 -> 23040 | M23: =M16-M18-M21 -> 5929 | N23: =N16-N18-N21 -> 7210 | O23: =O16-O18-O21 -> 6148 | P23: =P16-P18-P21 -> 4752 | Q23: =Q16-Q18-Q21 -> 24039 | R23: =R16-R18-R21 -> 5551 | S23: =S16-S18-S21 -> 6589 | ... Y23: =Y16-Y18-Y21 -> 5418
B24: Interest & Other (Income) Expense
B25: Interest and Investment Income: | C25: -17 | D25: -9 | E25: -11 | F25: =G25-C25-D25-E25 -> -10 | G25: -47 | H25: -6 | I25: -5 | J25: -15 | K25: =L25-H25-I25-J25 -> -18 | L25: -44 | M25: -3 | N25: -2 | O25: -7 | P25: =Q25-M25-N25-O25 -> -43 | Q25: -55 | R25: -33 | S25: -41 | T25: -49 | U25: =V25-R25-S25-T25 -> -55 | V25: -178 | W25: -57 | X25: -84 | Y25: -30
B26: Interest Expense: | C26: 324 | D26: 346 | E26: 340 | F26: =G26-C26-D26-E26 -> 337 | G26: 1347 | H26: 339 | I26: 326 | J26: 341 | K26: =L26-H26-I26-J26 -> 341 | L26: 1347 | M26: 372 | N26: 381 | O26: 413 | P26: =Q26-M26-N26-O26 -> 451 | Q26: 1617 | R26: 474 | S26: 469 | T26: 487 | U26: =V26-R26-S26-T26 -> 513 | V26: 1943 | W26: 485 | X26: 573 | Y26: 625
B27: Net Interest & Other | C27: =SUM(C25:C26) -> 307 | D27: =SUM(D25:D26) -> 337 | E27: =SUM(E25:E26) -> 329 | F27: =SUM(F25:F26) -> 327 | G27: =SUM(G25:G26) -> 1300 | H27: =SUM(H25:H26) -> 333 | I27: =SUM(I25:I26) -> 321 | J27: =SUM(J25:J26) -> 326 | ... Y27: =SUM(Y25:Y26) -> 595
B28: EBT | C28: =C23-C27 -> 2969 | D28: =D23-D27 -> 5730 | E28: =E23-E27 -> 4523 | F28: =F23-F27 -> 3756 | G28: =G23-G27 -> 16978 | H28: =H23-H27 -> 5448 | I28: =I23-I27 -> 6318 | J28: =J23-J27 -> 5469 | ... Y28: =Y23-Y27 -> 4823
B29: Provision for Income Taxes | C29: 724 | D29: 1398 | E29: 1091 | F29: =G29-C29-D29-E29 -> 899 | G29: 4112 | H29: 1303 | I29: 1511 | J29: 1340 | K29: =L29-H29-I29-J29 -> 1150 | L29: 5304 | M29: 1329 | N29: 1658 | O29: 1403 | P29: =Q29-M29-N29-O29 -> 982 | Q29: 5372 | R29: 1237 | S29: 1502 | T29: 1158 | U29: =V29-R29-S29-T29 -> 884 | V29: 4781 | W29: 1051 | X29: 1484 | Y29: 1175
B30: Income Tax Expense (%): | C30: =C29/C28 -> 0.24385315 | D30: =D29/D28 -> 0.24397906 | E30: =E29/E28 -> 0.24121159 | F30: =F29/F28 -> 0.23935037 | G30: =G29/G28 -> 0.24219578 | H30: =H29/H28 -> 0.23917034 | I30: =I29/I28 -> 0.23915796 | J30: =J29/J28 -> 0.24501737 | ... Y30: =Y29/Y28 -> 0.2436243
B31: Net Earnings (Net Income) | C31: =C28-C29 -> 2245 | D31: =D28-D29 -> 4332 | E31: =E28-E29 -> 3432 | F31: =F28-F29 -> 2857 | G31: =G28-G29 -> 12866 | H31: =H28-H29 -> 4145 | I31: =I28-I29 -> 4807 | J31: =J28-J29 -> 4129 | ... Y31: =Y28-Y29 -> 3648
B32: Earnings Per Share
B33: Basic EPS | C33: 2.09 | D33: 4.04 | E33: 3.2 | F33: =G33-C33-D33-E33 -> 2.65 | G33: 11.98 | H33: 3.87 | I33: 4.54 | J33: 3.94 | K33: =L33-H33-I33-J33 -> 3.24 | L33: 15.59 | M33: 4.11 | N33: 5.06 | O33: 4.25 | P33: =Q33-M33-N33-O33 -> 3.32 | Q33: 16.74 | R33: 3.83 | S33: 4.66 | T33: 3.83 | U33: =V33-R33-S33-T33 -> 2.84 | V33: 15.16 | W33: 3.64 | X33: 4.61 | Y33: 3.68
B34: Diluted EPS | C34: 2.08 | D34: 4.02 | E34: 3.18 | F34: =G34-C34-D34-E34 -> 2.66 | G34: 11.94 | H34: 3.86 | I34: 4.53 | J34: 3.92 | K34: =L34-H34-I34-J34 -> 3.22 | L34: 15.53 | M34: 4.09 | N34: 5.05 | O34: 4.24 | P34: =Q34-M34-N34-O34 -> 3.31 | Q34: 16.69 | R34: 3.82 | S34: 4.65 | T34: 3.81 | U34: =V34-R34-S34-T34 -> 2.83 | V34: 15.11 | W34: 3.63 | X34: 4.6 | Y34: 3.67
B35: Shares Used in Computing EPS
B36: Basic Weighted Average Common Shares | C36: 1073 | D36: 1073 | E36: 1073 | F36: 1074 | G36: 1074 | H36: 1071 | I36: 1058 | J36: 1049 | K36: 1054 | L36: 1054 | M36: 1030 | N36: 1023 | O36: 1020 | P36: 1022 | Q36: 1022 | R36: 1010 | S36: 1000 | T36: 996 | U36: 999 | V36: 999 | W36: 989 | X36: 990 | Y36: 991
B37: Diluted Weighted Average Common Shares | C37: 1077 | D37: 1077 | E37: 1078 | F37: 1078 | G37: 1078 | H37: 1075 | I37: 1062 | J37: 1053 | K37: 1058 | L37: 1058 | M37: 1034 | N37: 1025 | O37: 1023 | P37: 1025 | Q37: 1025 | R37: 1013 | S37: 1003 | T37: 999 | U37: 1002 | V37: 1002 | W37: 992 | X37: 992 | Y37: 993
B42: Balance Sheet
B43: Assets
B44: Cash & Cash Equivalents: | C44: 8696 | D44: 14139 | E44: 14652 | F44: 7895 | G44: 7895 | H44: 6648 | I44: 4566 | J44: 5067 | K44: 2343 | L44: 2343 | M44: 2844 | N44: 1259 | O44: 2462 | P44: 2757 | Q44: 2757 | R44: 1260 | S44: 2814 | T44: 2058 | U44: 3760 | V44: 3760 | W44: 4264 | X44: 1613 | Y44: 1531
B45: Receivables, Net: | C45: 2610 | D45: 2562 | E45: 2666 | F45: 2992 | G45: 2992 | H45: 3624 | I45: 3322 | J45: 3533 | K45: 3426 | L45: 3426 | M45: 3936 | N45: 3725 | O45: 3732 | P45: 3317 | Q45: 3317 | R45: 4213 | S45: 3836 | T45: 3932 | U45: 3328 | V45: 3328 | W45: 4105 | X45: 5503 | Y45: 5782
B46: Merchandise Inventories: | C46: 14989 | D46: 13498 | E46: 16155 | F46: 16627 | G46: 16627 | H46: 19178 | I46: 18909 | J46: 20582 | K46: 22068 | L46: 22068 | M46: 25297 | N46: 26088 | O46: 25719 | P46: 24886 | Q46: 24886 | R46: 25371 | S46: 23265 | T46: 22805 | U46: 20976 | V46: 20976 | W46: 22416 | X46: 23060 | Y46: 23897
B47: Other Current Assets: | C47: 982 | D47: 1162 | E47: 1032 | F47: 963 | G47: 963 | H47: 1222 | I47: 1465 | J47: 1284 | K47: 1218 | L47: 1218 | M47: 1790 | N47: 1869 | O47: 1768 | P47: 1511 | Q47: 1511 | R47: 1579 | S47: 1915 | T47: 1887 | U47: 1711 | V47: 1711 | W47: 1837 | X47: 2097 | Y47: 1739
B48: Total Current Assets | C48: =SUM(C44:C47) -> 27277 | D48: =SUM(D44:D47) -> 31361 | E48: =SUM(E44:E47) -> 34505 | F48: =SUM(F44:F47) -> 28477 | G48: =SUM(G44:G47) -> 28477 | H48: =SUM(H44:H47) -> 30672 | I48: =SUM(I44:I47) -> 28262 | J48: =SUM(J44:J47) -> 30466 | ... Y48: =SUM(Y44:Y47) -> 32949
B50: Net Property & Equipment | C50: 22697 | D50: 23387 | E50: 23848 | F50: 24705 | G50: 24705 | H50: 24673 | I50: 24750 | J50: 24935 | K50: 25199 | L50: 25199 | M50: 25166 | N50: 25247 | O50: 25240 | P50: 25631 | Q50: 25631 | R50: 25674 | S50: 25879 | T50: 25735 | U50: 26154 | V50: 26154 | W50: 25997 | X50: 26640 | Y50: 26573
...

Sheet Key Metrics
B1: Home Depot (NYSE: HD)
B2: Key Financial Ratios
B5: Period End: | C5: =DATE(2021,1,31) -> 44227 | D5: =DATE(2022,1,30) -> 44591 | E5: =DATE(2022,1,29) -> 44590 | F5: =DATE(2024,1,28) -> 45319
B6: USD millions (expect per share data) | C6: FY2021A | D6: FY2022A | E6: FY2023A | F6: FY2024A | G6: FY2025E | H6: FY2026E | I6: FY2027E | J6: FY2028E | K6: FY2029E | L6: FY2030E | M6: FY2031E
B9: Liquidity Ratios
B10: Current Ratio | C10: ='Annual Model'!C42/'Annual Model'!C63 -> 1.0780952 | D10: ='Annual Model'!D42/'Annual Model'!D63 -> 1.2292584 | E10: ='Annual Model'!E42/'Annual Model'!E63 -> 1.0126163 | F10: ='Annual Model'!F42/'Annual Model'!F63 -> 1.4050627 | G10: ='Annual Model'!G42/'Annual Model'!G63 -> 1.4391967 | H10: ='Annual Model'!H42/'Annual Model'!H63 -> 1.3799911 | I10: ='Annual Model'!I42/'Annual Model'!I63 -> 1.3169967 | J10: ='Annual Model'!J42/'Annual Model'!J63 -> 1.3146028 | ... M10: ='Annual Model'!M42/'Annual Model'!M63 -> 1.4247132
B11: Acid-Test Ratio | C11: =('Annual Model'!C42-'Annual Model'!C40)/'Annual Model'!C63 -> 0.28729252 | D11: =('Annual Model'!D42-'Annual Model'!D40)/'Annual Model'!D63 -> 0.51152551 | E11: =('Annual Model'!E42-'Annual Model'!E40)/'Annual Model'!E63 -> 0.24350887 | F11: =('Annual Model'!F42-'Annual Model'!F40)/'Annual Model'!F63 -> 0.32821289 | G11: =('Annual Model'!G42-'Annual Model'!G40)/'Annual Model'!G63 -> 0.50176159 | H11: =('Annual Model'!H42-'Annual Model'!H40)/'Annual Model'!H63 -> 0.45411265 | I11: =('Annual Model'!I42-'Annual Model'!I40)/'Annual Model'!I63 -> 0.39870184 | J11: =('Annual Model'!J42-'Annual Model'!J40)/'Annual Model'!J63 -> 0.40243697 | ... M11: =('Annual Model'!M42-'Annual Model'!M40)/'Annual Model'!M63 -> 0.5340101
B12: Cash Ratio | C12: ='Annual Model'!C38/'Annual Model'!C63 -> 0.11608163 | D12: ='Annual Model'!D38/'Annual Model'!D63 -> 0.34080117 | E12: ='Annual Model'!E38/'Annual Model'!E63 -> 0.081657547 | F12: ='Annual Model'!F38/'Annual Model'!F63 -> 0.119299 | G12: ='Annual Model'!G38/'Annual Model'!G63 -> 0.31271589 | H12: ='Annual Model'!H38/'Annual Model'!H63 -> 0.2741009 | I12: ='Annual Model'!I38/'Annual Model'!I63 -> 0.22686363 | J12: ='Annual Model'!J38/'Annual Model'!J63 -> 0.23805683 | ... M12: ='Annual Model'!M38/'Annual Model'!M63 -> 0.38917153
B13: Leverage Ratios
B14: Debt Ratio | C14: ='Annual Model'!C70/'Annual Model'!C50 -> 1.0608166 | D14: ='Annual Model'!D70/'Annual Model'!D50 -> 0.95325938 | E14: ='Annual Model'!E70/'Annual Model'!E50 -> 1.0235962 | F14: ='Annual Model'!F70/'Annual Model'!F50 -> 0.97956701 | G14: ='Annual Model'!G70/'Annual Model'!G50 -> 0.94791752 | H14: ='Annual Model'!H70/'Annual Model'!H50 -> 0.91021745 | I14: ='Annual Model'!I70/'Annual Model'!I50 -> 0.86491634 | J14: ='Annual Model'!J70/'Annual Model'!J50 -> 0.81484795 | ... M14: ='Annual Model'!M70/'Annual Model'!M50 -> 0.63825261
B15: D/E Ratio | C15: ='Annual Model'!C70/'Annual Model'!C79 -> 1.0608166 | D15: ='Annual Model'!D70/'Annual Model'!D79 -> 0.95325938 | E15: ='Annual Model'!E70/'Annual Model'!E79 -> 1.0235962 | F15: ='Annual Model'!F70/'Annual Model'!F79 -> 0.97956701 | G15: ='Annual Model'!G70/'Annual Model'!G79 -> 0.94791752 | H15: ='Annual Model'!H70/'Annual Model'!H79 -> 0.91021745 | I15: ='Annual Model'!I70/'Annual Model'!I79 -> 0.86491634 | J15: ='Annual Model'!J70/'Annual Model'!J79 -> 0.81484795 | ... M15: ='Annual Model'!M70/'Annual Model'!M79 -> 0.63825261
B16: Profitability Ratios
B17: ROA | C17: ='Annual Model'!C25/'Annual Model'!C50 -> 0.2511125 | D17: ='Annual Model'!D25/'Annual Model'!D50 -> 0.2328247 | E17: ='Annual Model'!E25/'Annual Model'!E50 -> 0.2379793 | F17: ='Annual Model'!F25/'Annual Model'!F50 -> 0.19809013 | G17: ='Annual Model'!G25/'Annual Model'!G50 -> 0.19066488 | H17: ='Annual Model'!H25/'Annual Model'!H50 -> 0.19842128 | I17: ='Annual Model'!I25/'Annual Model'!I50 -> 0.20891859 | J17: ='Annual Model'!J25/'Annual Model'!J50 -> 0.21593757 | ... M17: ='Annual Model'!M25/'Annual Model'!M50 -> 0.2247823
B18: ROE | C18: ='Annual Model'!C25/'Annual Model'!C78 -> -4.1290116 | D18: ='Annual Model'!D25/'Annual Model'!D78 -> 4.9812064 | E18: ='Annual Model'!E25/'Annual Model'!E78 -> -10.085495 | F18: ='Annual Model'!F25/'Annual Model'!F78 -> 9.6946223 | G18: ='Annual Model'!G25/'Annual Model'!G78 -> 3.6608257 | H18: ='Annual Model'!H25/'Annual Model'!H78 -> 2.2100206 | I18: ='Annual Model'!I25/'Annual Model'!I78 -> 1.5465867 | J18: ='Annual Model'!J25/'Annual Model'!J78 -> 1.1662716 | ... M18: ='Annual Model'!M25/'Annual Model'!M78 -> 0.62137918
B21: Cash Flow Ratios/Metrics
B22: FCF
B23: FCF | C23: ='Annual Model'!C105+'Annual Model'!C108 -> 16376 | D23: ='Annual Model'!D105+'Annual Model'!D108 -> 14005 | E23: ='Annual Model'!E105+'Annual Model'!E108 -> 11496 | F23: ='Annual Model'!F105+'Annual Model'!F108 -> 17946 | G23: ='Annual Model'!G105+'Annual Model'!G108 -> 19650.859 | H23: ='Annual Model'!H105+'Annual Model'!H108 -> 17240.631 | I23: ='Annual Model'!I105+'Annual Model'!I108 -> 17692.088 | J23: ='Annual Model'!J105+'Annual Model'!J108 -> 18322.039 | ... M23: ='Annual Model'!M105+'Annual Model'!M108 -> 20561.738
B24: FCF Growth % | D24: =D23/C23-1 -> -0.14478505 | E24: =E23/D23-1 -> -0.1791503 | F24: =F23/E23-1 -> 0.56106472 | G24: =G23/F23-1 -> 0.094999386 | H24: =H23/G23-1 -> -0.12265253 | I24: =I23/H23-1 -> 0.026185643 | J24: =J23/I23-1 -> 0.035606334 | K24: =K23/J23-1 -> 0.038609587 | ... M24: =M23/L23-1 -> 0.041407859
B26: UFCF
B27: EBIT | C27: ='Annual Model'!C17 -> 18278 | D27: ='Annual Model'!D17 -> 23040 | E27: ='Annual Model'!E17 -> 24039 | F27: ='Annual Model'!F17 -> 21689 | G27: ='Annual Model'!G17 -> 22075.783 | H27: ='Annual Model'!H17 -> 22579.235 | I27: ='Annual Model'!I17 -> 23317.23 | J27: ='Annual Model'!J17 -> 24147.594 | ... M27: ='Annual Model'!M17 -> 26390.009
B28: Operating Lease Interest Element | C28: 0 | D28: 0 | E28: 0 | F28: 0 | G28: 0 | H28: 0 | I28: 0 | J28: 0 | K28: 0 | L28: 0 | M28: 0
B29: Tax Rate | C29: ='Annual Model'!C24 -> 0.24219578 | D29: ='Annual Model'!D24 -> 0.24400791 | E29: ='Annual Model'!E24 -> 0.23899987 | F29: ='Annual Model'!F24 -> 0.23996186 | G29: ='Annual Model'!G24 -> 0.24 | H29: ='Annual Model'!H24 -> 0.24 | I29: ='Annual Model'!I24 -> 0.24 | J29: ='Annual Model'!J24 -> 0.24 | ... M29: ='Annual Model'!M24 -> 0.24
B30: NOPAT | C30: =C27*(1-C29) -> 13851.145 | D30: =D27*(1-D29) -> 17418.058 | E30: =E27*(1-E29) -> 18293.682 | F30: =F27*(1-F29) -> 16484.467 | G30: =G27*(1-G29) -> 16777.595 | H30: =H27*(1-H29) -> 17160.219 | I30: =I27*(1-I29) -> 17721.095 | J30: =J27*(1-J29) -> 18352.171 | ... M30: =M27*(1-M29) -> 20056.407
B31: D&A | C31: ='Annual Model'!C88 -> 2519 | D31: ='Annual Model'!D88 -> 2862 | E31: ='Annual Model'!E88 -> 2975 | F31: ='Annual Model'!F88 -> 3247 | G31: ='Annual Model'!G88 -> 3411.3957 | H31: ='Annual Model'!H88 -> 3570.2173 | I31: ='Annual Model'!I88 -> 3735.3917 | J31: ='Annual Model'!J88 -> 3907.6686 | ... M31: ='Annual Model'!M88 -> 4465.1162
B32: Deferred Income Taxes | C32: ='Annual Model'!C93 -> -569 | D32: ='Annual Model'!D93 -> -276 | E32: ='Annual Model'!E93 -> 138 | F32: ='Annual Model'!F93 -> -245 | G32: ='Annual Model'!G93 -> 678.81341 | H32: ='Annual Model'!H93 -> 688.53216 | I32: ='Annual Model'!I93 -> 497.61854 | J32: ='Annual Model'!J93 -> 341.98312 | ... M32: ='Annual Model'!M93 -> 117.08914
B33: Change in Working Capital | C33: ='Annual Model'!C103 -> 2847 | D33: ='Annual Model'!D103 -> -3488 | E33: ='Annual Model'!E103 -> -5403 | F33: ='Annual Model'!F103 -> 2835 | G33: ='Annual Model'!G103 -> 2655.6604 | H33: ='Annual Model'!H103 -> -361.41704 | I33: ='Annual Model'!I103 -> -492.01155 | J33: ='Annual Model'!J103 -> -549.87678 | ... M33: ='Annual Model'!M103 -> -510.7898
B34: CAPEX | C34: ='Annual Model'!C108 -> -2463 | D34: ='Annual Model'!D108 -> -2566 | E34: ='Annual Model'!E108 -> -3119 | F34: ='Annual Model'!F108 -> -3226 | G34: ='Annual Model'!G108 -> -3083.9138 | H34: ='Annual Model'!H108 -> -3176.4312 | I34: ='Annual Model'!I108 -> -3303.4885 | J34: ='Annual Model'!J108 -> -3445.5385 | ... M34: ='Annual Model'!M108 -> -3847.8568
B35: UFCF | C35: =SUM(C30:C34) -> 16185.145 | D35: =SUM(D30:D34) -> 13950.058 | E35: =SUM(E30:E34) -> 12884.682 | F35: =SUM(F30:F34) -> 19095.467 | G35: =SUM(G30:G34) -> 20439.551 | H35: =SUM(H30:H34) -> 17881.12 | I35: =SUM(I30:I34) -> 18158.605 | J35: =SUM(J30:J34) -> 18606.408 | ... M35: =SUM(M30:M34) -> 20279.966
B36: UFCF Margin % | C36: =C35/'Annual Model'!C10 -> 0.12251264 | D36: =D35/'Annual Model'!D10 -> 0.092288532 | E36: =E35/'Annual Model'!E10 -> 0.08185792 | F36: =F35/'Annual Model'!F10 -> 0.12507757 | G36: =G35/'Annual Model'!G10 -> 0.13255591 | H36: =H35/'Annual Model'!H10 -> 0.11258622 | I36: =I35/'Annual Model'!I10 -> 0.10993594 | J36: =J35/'Annual Model'!J10 -> 0.1080029 | ... M36: =M35/'Annual Model'!M10 -> 0.10540915
B38: LFCF
B39: Net Income | C39: ='Annual Model'!C25 -> 12866 | D39: ='Annual Model'!D25 -> 16433 | E39: ='Annual Model'!E25 -> 17105 | F39: ='Annual Model'!F25 -> 15143 | G39: ='Annual Model'!G25 -> 15201.47 | H39: ='Annual Model'!H25 -> 15671.39 | I39: ='Annual Model'!I25 -> 16331.91 | J39: ='Annual Model'!J25 -> 17063.092 | ... M39: ='Annual Model'!M25 -> 19079.233
B40: D&A | C40: ='Annual Model'!C88 -> 2519 | D40: ='Annual Model'!D88 -> 2862 | E40: ='Annual Model'!E88 -> 2975 | F40: ='Annual Model'!F88 -> 3247 | G40: ='Annual Model'!G88 -> 3411.3957 | H40: ='Annual Model'!H88 -> 3570.2173 | I40: ='Annual Model'!I88 -> 3735.3917 | J40: ='Annual Model'!J88 -> 3907.6686 | ... M40: ='Annual Model'!M88 -> 4465.1162
B41: Deferred Income Taxes | C41: ='Annual Model'!C93 -> -569 | D41: ='Annual Model'!D93 -> -276 | E41: ='Annual Model'!E93 -> 138 | F41: ='Annual Model'!F93 -> -245 | G41: ='Annual Model'!G93 -> 678.81341 | H41: ='Annual Model'!H93 -> 688.53216 | I41: ='Annual Model'!I93 -> 497.61854 | J41: ='Annual Model'!J93 -> 341.98312 | ... M41: ='Annual Model'!M93 -> 117.08914
B42: Change in Working Capital | C42: ='Annual Model'!C103 -> 2847 | D42: ='Annual Model'!D103 -> -3488 | E42: ='Annual Model'!E103 -> -5403 | F42: ='Annual Model'!F103 -> 2835 | G42: ='Annual Model'!G103 -> 2655.6604 | H42: ='Annual Model'!H103 -> -361.41704 | I42: ='Annual Model'!I103 -> -492.01155 | J42: ='Annual Model'!J103 -> -549.87678 | ... M42: ='Annual Model'!M103 -> -510.7898
B43: CAPEX | C43: ='Annual Model'!C108 -> -2463 | D43: ='Annual Model'!D108 -> -2566 | E43: ='Annual Model'!E108 -> -3119 | F43: ='Annual Model'!F108 -> -3226 | G43: ='Annual Model'!G108 -> -3083.9138 | H43: ='Annual Model'!H108 -> -3176.4312 | I43: ='Annual Model'!I108 -> -3303.4885 | J43: ='Annual Model'!J108 -> -3445.5385 | ... M43: ='Annual Model'!M108 -> -3847.8568
B44: Repayments of Debt Principal | C44: ='Annual Model'!C117 -> -2872 | D44: ='Annual Model'!D117 -> -1532 | E44: ='Annual Model'!E117 -> -2491 | F44: ='Annual Model'!F117 -> -1271 | G44: ='Annual Model'!G117 -> -1100 | H44: ='Annual Model'!H117 -> -2750 | I44: ='Annual Model'!I117 -> -3050 | J44: ='Annual Model'!J117 -> -2500 | ... M44: ='Annual Model'!M117 -> -2500
B45: New Debt Issuances | C45: 0 | D45: 0 | E45: 0 | F45: 0 | G45: 0 | H45: 0 | I45: 0 | J45: 0 | K45: 0 | L45: 0 | M45: 0
B46: LFCF | C46: =SUM(C39:C45) -> 12328 | D46: =SUM(D39:D45) -> 11433 | E46: =SUM(E39:E45) -> 9205 | F46: =SUM(F39:F45) -> 16483 | G46: =SUM(G39:G45) -> 17763.426 | H46: =SUM(H39:H45) -> 13642.291 | I46: =SUM(I39:I45) -> 13719.42 | J46: =SUM(J39:J45) -> 14817.328 | ... M46: =SUM(M39:M45) -> 16802.792
B47: LFCF Margin % | C47: =C46/'Annual Model'!C10 -> 0.093316176 | D47: =D46/'Annual Model'!D10 -> 0.07563659 | E47: =E46/'Annual Model'!E10 -> 0.058480461 | F47: =F46/'Annual Model'!F10 -> 0.1079656 | G47: =G46/'Annual Model'!G10 -> 0.11520054 | H47: =H46/'Annual Model'!H10 -> 0.085896973 | I47: =I46/'Annual Model'!I10 -> 0.083060195 | J47: =J46/'Annual Model'!J10 -> 0.086008781 | ... M47: =M46/'Annual Model'!M10 -> 0.087335848

Sheet DCF
B1: Home Depot (NYSE: HD)
B2: Discounted Cash Flow Analysis
B3: Sensitivity Tables
B5: Period End: | C5: =DATE(2021,1,31) -> 44227 | D5: =DATE(2022,1,30) -> 44591 | E5: =DATE(2022,1,29) -> 44590 | F5: =DATE(2024,1,28) -> 45319 | G5: Projections
B6: USD millions (expect per share data) | C6: FY2021A | D6: FY2022A | E6: FY2023A | F6: FY2024A | G6: FY2025E | H6: FY2026E | I6: FY2027E | J6: FY2028E | K6: FY2029E | L6: FY2030E | M6: FY2031E
B10: Discounted Cash Flow Analysis | P10: Gordon Growth Method | S10: Multiple Method
B11: Revenue | C11: ='Annual Model'!C10 -> 132110 | D11: ='Annual Model'!D10 -> 151157 | E11: ='Annual Model'!E10 -> 157403 | F11: ='Annual Model'!F10 -> 152669 | G11: ='Annual Model'!G10 -> 154195.69 | H11: ='Annual Model'!H10 -> 158821.56 | I11: ='Annual Model'!I10 -> 165174.42 | J11: ='Annual Model'!J10 -> 172276.92 | ... M11: ='Annual Model'!M10 -> 192392.84 | P11: Sum of PV UFCF | Q11: =SUM(G37:M37) -> 89503.912 | S11: Sum of PV UFCF | T11: =SUM(G37:M37) -> 89503.912
B12: % Growth | D12: =D11/C11-1 -> 0.14417531 | E12: =E11/D11-1 -> 0.041321275 | F12: =F11/E11-1 -> -0.030075666 | G12: =G11/F11-1 -> 0.01 | H12: =H11/G11-1 -> 0.03 | I12: =I11/H11-1 -> 0.04 | J12: =J11/I11-1 -> 0.043 | K12: =K11/J11-1 -> 0.04 | ... M12: =M11/L11-1 -> 0.035 | P12: Terminal Year UFCF | Q12: =M33 -> 18824.051 | S12: Exit Year EBITDA | T12: =M18 -> 29516.3
B13: Cost of Sales | C13: ='Annual Model'!C11 -> 87257 | D13: ='Annual Model'!D11 -> 100325 | E13: ='Annual Model'!E11 -> 104625 | F13: ='Annual Model'!F11 -> 101709 | G13: ='Annual Model'!G11 -> 102848.53 | H13: ='Annual Model'!H11 -> 106092.8 | I13: ='Annual Model'!I11 -> 110501.69 | J13: ='Annual Model'!J11 -> 115425.54 | ... M13: ='Annual Model'!M11 -> 129480.38 | P13: Perpetuity Growth Rate | Q13: 0.021 | S13: EBITDA Multiple | T13: =WACC!G21/DCF!T12 -> 15.21882
B14: Gross Margin % | C14: =C15/C11 -> 0.33951253 | D14: =D15/D11 -> 0.33628611 | E14: =E15/E11 -> 0.33530492 | F14: =F15/F11 -> 0.33379402 | G14: =G15/G11 -> 0.333 | H14: =H15/H11 -> 0.332 | I14: =I15/I11 -> 0.331 | J14: =J15/J11 -> 0.33 | ... M14: =M15/M11 -> 0.327 | P14: Terminal Value | Q14: =(Q12*(1+Q13)/(M35-Q13)) -> 290380.68 | S14: Terminal Value | T14: =T12*T13 -> 449203.26
B15: Gross Profit | C15: =C11-C13 -> 44853 | D15: =D11-D13 -> 50832 | E15: =E11-E13 -> 52778 | F15: =F11-F13 -> 50960 | G15: =G11-G13 -> 51347.165 | H15: =H11-H13 -> 52728.758 | I15: =I11-I13 -> 54672.734 | J15: =J11-J13 -> 56851.385 | ... M15: =M11-M13 -> 62912.458 | P15: PV of Terminal Value | Q15: =Q14/(1+M35)^M34 -> 161747.89 | S15: PV of Terminal Value | T15: =T14/(1+M35)^M34 -> 250215.27
B16: Selling, General, and Administrative: | C16: ='Annual Model'!C14 -> 24447 | D16: ='Annual Model'!D14 -> 25406 | E16: ='Annual Model'!E14 -> 26284 | F16: ='Annual Model'!F14 -> 26598 | G16: ='Annual Model'!G14 -> 26765.776 | H16: ='Annual Model'!H14 -> 27568.749 | I16: ='Annual Model'!I14 -> 28671.499 | J16: ='Annual Model'!J14 -> 29904.374 | ... M16: ='Annual Model'!M14 -> 33396.158 | P16: Enterprise Value | Q16: =Q15+Q11 -> 251251.81 | S16: Enterprise Value | T16: =T11+T15 -> 339719.19
