Workbook

Sheet Cover

Sheet Summary
B1: Lowe's (NYSE: LOW)
B2: Model Assumptions/Drivers
B6: Period End | C6: 43861 | D6: 44225 | E6: 44589 | F6: 44960 | G6: 45324
B7: USD Millions (Expect per Share Data) | C7: 2020A | D7: 2021A | E7: 2022A | F7: 2023A | G7: 2024A | H7: 2025E | I7: 2026E | J7: 2027E | K7: 2028E | L7: 2029E
B10: Income Statement
B11: Revenue | C11: ='Annual Model'!C11 -> 72148 | D11: ='Annual Model'!D11 -> 89597 | E11: ='Annual Model'!E11 -> 96250 | F11: ='Annual Model'!F11 -> 97059 | G11: ='Annual Model'!G11 -> 86377 | H11: ='Annual Model'!H11 -> 84001.633 | I11: ='Annual Model'!I11 -> 85261.657 | J11: ='Annual Model'!J11 -> 88075.292 | ... L11: ='Annual Model'!L11 -> 95262.235
B12: Growth % | D12: =D11/C11-1 -> 0.24185009 | E12: =E11/D11-1 -> 0.074254718 | F12: =F11/E11-1 -> 0.0084051948 | G12: =G11/F11-1 -> -0.11005677 | H12: =H11/G11-1 -> -0.0275 | I12: =I11/H11-1 -> 0.015 | J12: =J11/I11-1 -> 0.033 | K12: =K11/J11-1 -> 0.04 | L12: =L11/K11-1 -> 0.04
B13: COGS | C13: ='Annual Model'!C12 -> 49205 | D13: ='Annual Model'!D12 -> 60025 | E13: ='Annual Model'!E12 -> 64194 | F13: ='Annual Model'!F12 -> 64802 | G13: ='Annual Model'!G12 -> 57533 | H13: ='Annual Model'!H12 -> 55777.084 | I13: ='Annual Model'!I12 -> 56571.109 | J13: ='Annual Model'!J12 -> 58393.918 | ... L13: ='Annual Model'!L12 -> 63111.231
B14: COGS % Rev | C14: =C13/C11 -> 0.68200089 | D14: =D13/D11 -> 0.66994431 | E14: =E13/E11 -> 0.66695065 | F14: =F13/F11 -> 0.66765576 | G14: =G13/G11 -> 0.66606851 | H14: =H13/H11 -> 0.664 | I14: =I13/I11 -> 0.6635 | J14: =J13/J11 -> 0.663 | ... L14: =L13/L11 -> 0.6625
B15: COGS Growth % | D15: =D13/C13-1 -> 0.21989635 | E15: =E13/D13-1 -> 0.069454394 | F15: =F13/E13-1 -> 0.0094712902 | G15: =G13/F13-1 -> -0.11217246 | H15: =H13/G13-1 -> -0.030520154 | I15: =I13/H13-1 -> 0.014235693 | J15: =J13/I13-1 -> 0.032221552 | K15: =K13/J13-1 -> 0.039215686 | L15: =L13/K13-1 -> 0.04
B16: Gross Profit | C16: =C11-C13 -> 22943 | D16: =D11-D13 -> 29572 | E16: =E11-E13 -> 32056 | F16: =F11-F13 -> 32257 | G16: =G11-G13 -> 28844 | H16: =H11-H13 -> 28224.549 | I16: =I11-I13 -> 28690.548 | J16: =J11-J13 -> 29681.373 | ... L16: =L11-L13 -> 32151.004
B17: Gross Margin % | C17: =C16/C11 -> 0.31799911 | D17: =D16/D11 -> 0.33005569 | E17: =E16/E11 -> 0.33304935 | F17: =F16/F11 -> 0.33234424 | G17: =G16/G11 -> 0.33393149 | H17: =H16/H11 -> 0.336 | I17: =I16/I11 -> 0.3365 | J17: =J16/J11 -> 0.337 | ... L17: =L16/L11 -> 0.3375
B18: EBITDA | C18: ='Annual Model'!C31 -> 7724 | D18: ='Annual Model'!D31 -> 11241 | E18: ='Annual Model'!E31 -> 13975 | F18: ='Annual Model'!F31 -> 12140 | G18: ='Annual Model'!G31 -> 13480 | H18: ='Annual Model'!H31 -> 11424.222 | I18: ='Annual Model'!I31 -> 11638.216 | J18: ='Annual Model'!J31 -> 12066.315 | ... L18: ='Annual Model'!L31 -> 13098.557
B19: YoY Growth % | D19: =D18/C18-1 -> 0.45533402 | E19: =E18/D18-1 -> 0.2432168 | F19: =F18/E18-1 -> -0.1313059 | G19: =G18/F18-1 -> 0.11037891 | H19: =H18/G18-1 -> -0.15250578 | I19: =I18/H18-1 -> 0.018731618 | J19: =J18/I18-1 -> 0.036783883 | K19: =K18/J18-1 -> 0.04379562 | L19: =L18/K18-1 -> 0.04
B20: EBITDA Margin % | C20: =C18/C11 -> 0.10705771 | D20: =D18/D11 -> 0.12546179 | E20: =E18/E11 -> 0.14519481 | F20: =F18/F11 -> 0.12507856 | G20: =G18/G11 -> 0.15606006 | H20: =H18/H11 -> 0.136 | I20: =I18/I11 -> 0.1365 | J20: =J18/J11 -> 0.137 | ... L20: =L18/L11 -> 0.1375
B21: EBIT | C21: ='Annual Model'!C17 -> 6314 | D21: ='Annual Model'!D17 -> 9647 | E21: ='Annual Model'!E17 -> 12093 | F21: ='Annual Model'!F17 -> 10159 | G21: ='Annual Model'!G17 -> 11557 | H21: ='Annual Model'!H17 -> 9740.4423 | I21: ='Annual Model'!I17 -> 9879.4062 | J21: ='Annual Model'!J17 -> 10237.045 | ... L21: ='Annual Model'!L17 -> 11119.799
B22: Operating Margin % | C22: =C21/C11 -> 0.087514553 | D22: =D21/D11 -> 0.10767102 | E22: =E21/E11 -> 0.12564156 | F22: =F21/F11 -> 0.10466829 | G22: =G21/G11 -> 0.13379719 | H22: =H21/H11 -> 0.11595539 | I22: =I21/I11 -> 0.11587162 | J22: =J21/J11 -> 0.11623061 | ... L22: =L21/L11 -> 0.1167283
B23: Growth Rate % | D23: =D21/C21-1 -> 0.52787456 | E23: =E21/D21-1 -> 0.25355033 | F23: =F21/E21-1 -> -0.15992723 | G23: =G21/F21-1 -> 0.13761197 | H23: =H21/G21-1 -> -0.15718246 | I23: =I21/H21-1 -> 0.014266693 | J23: =J21/I21-1 -> 0.036200409 | K23: =K21/J21-1 -> 0.044463331 | L23: =L21/K21-1 -> 0.039989915
B24: EBT | C24: ='Annual Model'!C20 -> 5623 | D24: ='Annual Model'!D20 -> 7739 | E24: ='Annual Model'!E20 -> 11208 | F24: ='Annual Model'!F20 -> 9036 | G24: ='Annual Model'!G20 -> 10175 | H24: ='Annual Model'!H20 -> 8379.1723 | I24: ='Annual Model'!I20 -> 8562.3775 | J24: ='Annual Model'!J20 -> 8959.5269 | ... L24: ='Annual Model'!L20 -> 9905.3583
B25: EBT Margin % | C25: =C24/C11 -> 0.077937018 | D25: =D24/D11 -> 0.08637566 | E25: =E24/E11 -> 0.11644675 | F25: =F24/F11 -> 0.093098013 | G25: =G24/G11 -> 0.11779756 | H25: =H24/H11 -> 0.099750113 | I25: =I24/I11 -> 0.10042471 | J25: =J24/J11 -> 0.10172577 | ... L25: =L24/L11 -> 0.10397991
B26: Net Earnings (Income) | C26: ='Annual Model'!C23 -> 4281 | D26: ='Annual Model'!D23 -> 5835 | E26: ='Annual Model'!E23 -> 8442 | F26: ='Annual Model'!F23 -> 6437 | G26: ='Annual Model'!G23 -> 7726 | H26: ='Annual Model'!H23 -> 6267.9686 | I26: ='Annual Model'!I23 -> 6405.0137 | J26: ='Annual Model'!J23 -> 6702.0979 | ... L26: ='Annual Model'!L23 -> 7409.6191
B27: Growth % | D27: =D26/C26-1 -> 0.3629993 | E27: =E26/D26-1 -> 0.44678663 | F27: =F26/E26-1 -> -0.23750296 | G27: =G26/F26-1 -> 0.20024856 | H27: =H26/G26-1 -> -0.1887175 | I27: =I26/H26-1 -> 0.021864352 | J27: =J26/I26-1 -> 0.046383076 | K27: =K26/J26-1 -> 0.054367944 | L27: =L26/K26-1 -> 0.048559115

Sheet Assumptions
B1: Lowe's (NYSE: LOW)
B2: Model Assumptions/Drivers
B6: Period End | C6: 43861 | D6: 44225 | E6: 44589 | F6: 44960 | G6: 45324
B7: USD Millions (Expect per Share Data) | C7: 2020A | D7: 2021A | E7: 2022A | F7: 2023A | G7: 2024A | H7: 2025E | I7: 2026E | J7: 2027E | K7: 2028E | L7: 2029E
B10: Income Statement
B11: Revenue Growth YoY (%) | D11: ='Annual Model'!D11/'Annual Model'!C11-1 -> 0.24185009 | E11: ='Annual Model'!E11/'Annual Model'!D11-1 -> 0.074254718 | F11: ='Annual Model'!F11/'Annual Model'!E11-1 -> 0.0084051948 | G11: ='Annual Model'!G11/'Annual Model'!F11-1 -> -0.11005677 | H11: -0.0275 | I11: 0.015 | J11: 0.033 | K11: 0.04 | L11: 0.04
B12: Cost of Sales % Rev | C12: ='Annual Model'!C12/'Annual Model'!C11 -> 0.68200089 | D12: ='Annual Model'!D12/'Annual Model'!D11 -> 0.66994431 | E12: ='Annual Model'!E12/'Annual Model'!E11 -> 0.66695065 | F12: ='Annual Model'!F12/'Annual Model'!F11 -> 0.66765576 | G12: ='Annual Model'!G12/'Annual Model'!G11 -> 0.66606851 | H12: 0.664 | I12: 0.6635 | J12: 0.663 | K12: 0.6625 | L12: 0.6625
B13: SG&A % Rev | C13: ='Annual Model'!C15/'Annual Model'!C11 -> 0.21299274 | D13: ='Annual Model'!D15/'Annual Model'!D11 -> 0.20677032 | E13: ='Annual Model'!E15/'Annual Model'!E11 -> 0.19014026 | F13: ='Annual Model'!F15/'Annual Model'!F11 -> 0.20948083 | G13: ='Annual Model'!G15/'Annual Model'!G11 -> 0.18025632 | H13: 0.2 | I13: 0.2 | J13: 0.2 | K13: 0.2 | L13: 0.2
B14: Loss on Extinguishment of Debt | C14: ='Annual Model'!C19 -> 0 | D14: ='Annual Model'!D19 -> 1060 | E14: ='Annual Model'!E19 -> 0 | F14: ='Annual Model'!F19 -> 0 | G14: ='Annual Model'!G19 -> 0 | H14: 0 | I14: 0 | J14: 0 | K14: 0 | L14: 0
B15: Tax Rate (%) | C15: ='Annual Model'!C22 -> 0.23866264 | D15: ='Annual Model'!D22 -> 0.24602662 | E15: ='Annual Model'!E22 -> 0.24678801 | F15: ='Annual Model'!F22 -> 0.28762727 | G15: ='Annual Model'!G22 -> 0.24068796 | H15: =AVERAGE(C15:G15) -> 0.2519585 | I15: =H15 -> 0.2519585 | J15: =I15 -> 0.2519585 | K15: =J15 -> 0.2519585 | L15: =K15 -> 0.2519585
B16: Shares Used in Computing EPS (Basic) | C16: ='Annual Model'!C28 -> 779.78142 | D16: ='Annual Model'!D28 -> 750.96525 | E16: ='Annual Model'!E28 -> 699.42005 | F16: ='Annual Model'!F28 -> 631.07843 | G16: ='Annual Model'!G28 -> 583.97581 | H16: =G16*(1+H17) -> 554.77702 | I16: =H16*(1+I17) -> 527.03817 | J16: =I16*(1+J17) -> 505.95664 | K16: =J16*(1+K17) -> 490.77794 | L16: =K16*(1+L17) -> 476.05461
B17: YoY Change (%) | D17: =D16/C16-1 -> -0.036954163 | E17: =E16/D16-1 -> -0.068638597 | F17: =F16/E16-1 -> -0.097711838 | G17: =G16/F16-1 -> -0.074638296 | H17: -0.05 | I17: -0.05 | J17: -0.04 | K17: -0.03 | L17: -0.03
B18: Shares Used in Computing EPS (Diluted) | C18: ='Annual Model'!C29 -> 779.78142 | D18: ='Annual Model'!D29 -> 752.90323 | E18: ='Annual Model'!E29 -> 701.16279 | F18: ='Annual Model'!F29 -> 632.94002 | G18: ='Annual Model'!G29 -> 585.30303 | H18: =G18*(1+H19) -> 556.03788 | I18: =H18*(1+I19) -> 528.23598 | J18: =I18*(1+J19) -> 507.10655 | K18: =J18*(1+K19) -> 491.89335 | L18: =K18*(1+L19) -> 477.13655
B19: YoY Change (%) | D19: =D18/C18-1 -> -0.034468884 | E19: =E18/D18-1 -> -0.068721229 | F19: =F18/E18-1 -> -0.097299474 | G19: =G18/F18-1 -> -0.075263039 | H19: -0.05 | I19: -0.05 | J19: -0.04 | K19: -0.03 | L19: -0.03
B20: Interest - Net | C20: ='Annual Model'!C18 -> 691 | D20: ='Annual Model'!D18 -> 848 | E20: ='Annual Model'!E18 -> 885 | F20: ='Annual Model'!F18 -> 1123 | G20: ='Annual Model'!G18 -> 1382 | H20: =G20*(1+H21) -> 1361.27 | I20: =H20*(1+I21) -> 1317.0287 | J20: =I20*(1+J21) -> 1277.5179 | K20: =J20*(1+K21) -> 1245.5799 | L20: =K20*(1+L21) -> 1214.4404
B21: YoY Change (%) | D21: =D20/C20-1 -> 0.22720695 | E21: =E20/D20-1 -> 0.043632075 | F21: =F20/E20-1 -> 0.26892655 | G21: =G20/F20-1 -> 0.23063224 | H21: -0.015 | I21: -0.0325 | J21: -0.03 | K21: -0.025 | L21: -0.025
B23: Balance Sheet
B24: Short-Term Investments % Rev | C24: ='Annual Model'!C36/'Annual Model'!C11 -> 0.0022176637 | D24: ='Annual Model'!D36/'Annual Model'!D11 -> 0.0056475105 | E24: ='Annual Model'!E36/'Annual Model'!E11 -> 0.0028155844 | F24: ='Annual Model'!F36/'Annual Model'!F11 -> 0.0039563564 | G24: ='Annual Model'!G36/'Annual Model'!G11 -> 0.0035541869 | H24: =AVERAGE(C24:G24) -> 0.0036382604 | I24: =H24 -> 0.0036382604 | J24: =I24 -> 0.0036382604 | K24: =J24 -> 0.0036382604 | L24: =K24 -> 0.0036382604
B25: Operating Lease ROU Assets | C25: ='Annual Model'!C41 -> 3891 | D25: ='Annual Model'!D41 -> 3832 | E25: ='Annual Model'!E41 -> 4108 | F25: ='Annual Model'!F41 -> 3518 | G25: ='Annual Model'!G41 -> 3733 | H25: 3733 | I25: 3733 | J25: 3733 | K25: 3733 | L25: 3733
B27: Current Maturities of Long-Term Debt | C27: ='Annual Model'!C50 -> 597 | D27: ='Annual Model'!D50 -> 1112 | E27: ='Annual Model'!E50 -> 868 | F27: ='Annual Model'!F50 -> 585 | G27: ='Annual Model'!G50 -> 537 | H27: 537 | I27: 537 | J27: 537 | K27: 537 | L27: 537
B28: Current Operating Lease Liabilities | C28: ='Annual Model'!C51 -> 501 | D28: ='Annual Model'!D51 -> 541 | E28: ='Annual Model'!E51 -> 636 | F28: ='Annual Model'!F51 -> 522 | G28: ='Annual Model'!G51 -> 487 | H28: 487 | I28: 487 | J28: 487 | K28: 487 | L28: 487
B29: Accrued Compensation and Employee Benefits | C29: ='Annual Model'!C53 -> 684 | D29: ='Annual Model'!D53 -> 1350 | E29: ='Annual Model'!E53 -> 1561 | F29: ='Annual Model'!F53 -> 1109 | G29: ='Annual Model'!G53 -> 954 | H29: 954 | I29: 954 | J29: 954 | K29: 954 | L29: 954
B33: Cash Flow Statement
B34: Noncash Lease Expense % Rev | C34: ='Annual Model'!C84/'Annual Model'!C11 -> 0.0064866663 | D34: ='Annual Model'!D84/'Annual Model'!D11 -> 0.0053461611 | E34: ='Annual Model'!E84/'Annual Model'!E11 -> 0.0053714286 | F34: ='Annual Model'!F84/'Annual Model'!F11 -> 0.0054605961 | G34: ='Annual Model'!G84/'Annual Model'!G11 -> 0.0057770008 | H34: =AVERAGE(C34:G34) -> 0.0056883706 | I34: =H34 -> 0.0056883706 | J34: =I34 -> 0.0056883706 | K34: =J34 -> 0.0056883706 | L34: =K34 -> 0.0056883706
B35: Asset Impairment and Loss on Property - Net | C35: ='Annual Model'!C86 -> 117 | D35: ='Annual Model'!D86 -> 139 | E35: ='Annual Model'!E86 -> 34 | F35: ='Annual Model'!F86 -> 2118 | G35: ='Annual Model'!G86 -> 83 | H35: 83 | I35: 83 | J35: 83 | K35: 83 | L35: 83
B36: Impairment of Goodwill | C36: ='Annual Model'!C87 -> 0 | D36: ='Annual Model'!D87 -> 0 | E36: ='Annual Model'!E87 -> 0 | F36: ='Annual Model'!F87 -> 421 | G36: ='Annual Model'!G87 -> -79 | H36: 0 | I36: 0 | J36: 0 | K36: 0 | L36: 0
B37: Gain/(Loss) on Sale of Business | C37: ='Annual Model'!C88 -> 0 | D37: ='Annual Model'!D88 -> 0 | E37: ='Annual Model'!E88 -> 0 | F37: ='Annual Model'!F88 -> 0 | G37: ='Annual Model'!G88 -> 0 | H37: 0 | I37: 0 | J37: 0 | K37: 0 | L37: 0
B38: Loss on Extinguishment of Debt | C38: ='Annual Model'!C89 -> 0 | D38: ='Annual Model'!D89 -> 1060 | E38: ='Annual Model'!E89 -> 0 | F38: ='Annual Model'!F89 -> 0 | G38: ='Annual Model'!G89 -> 0 | H38: 0 | I38: 0 | J38: 0 | K38: 0 | L38: 0
B39: Share-Based Payment Expense % Rev | C39: ='Annual Model'!C90/'Annual Model'!C11 -> 0.001358319 | D39: ='Annual Model'!D90/'Annual Model'!D11 -> 0.0017299686 | E39: ='Annual Model'!E90/'Annual Model'!E11 -> 0.0023896104 | F39: ='Annual Model'!F90/'Annual Model'!F11 -> 0.0022975716 | G39: ='Annual Model'!G90/'Annual Model'!G11 -> 0.0024312028 | H39: 0.0025 | I39: 0.0025 | J39: 0.0025 | K39: 0.0025 | L39: 0.0025
B41: Purchases of Investments % Rev | C41: =-'Annual Model'!C102/'Annual Model'!C11 -> 0.010298276 | D41: =-'Annual Model'!D102/'Annual Model'!D11 -> 0.034532406 | E41: =-'Annual Model'!E102/'Annual Model'!E11 -> 0.031844156 | F41: =-'Annual Model'!F102/'Annual Model'!F11 -> 0.012250281 | G41: =-'Annual Model'!G102/'Annual Model'!G11 -> 0.020665223 | H41: =AVERAGE(C41:G41) -> 0.021918068 | I41: =H41 -> 0.021918068 | J41: =I41 -> 0.021918068 | K41: =J41 -> 0.021918068 | L41: =K41 -> 0.021918068
B42: Proceeds From Sale/Maturity of Investments % Rev | C42: ='Annual Model'!C103/'Annual Model'!C11 -> 0.0096329767 | D42: ='Annual Model'!D103/'Annual Model'!D11 -> 0.032657343 | E42: ='Annual Model'!E103/'Annual Model'!E11 -> 0.034212987 | F42: ='Annual Model'!F103/'Annual Model'!F11 -> 0.012095736 | G42: ='Annual Model'!G103/'Annual Model'!G11 -> 0.019935863 | H42: =AVERAGE(C42:G42) -> 0.021706981 | I42: =H42 -> 0.021706981 | J42: =I42 -> 0.021706981 | K42: =J42 -> 0.021706981 | L42: =K42 -> 0.021706981
B43: CAPEX % Rev | C43: =-'Annual Model'!C104/'Annual Model'!C11 -> 0.020568831 | D43: =-'Annual Model'!D104/'Annual Model'!D11 -> 0.019989509 | E43: =-'Annual Model'!E104/'Annual Model'!E11 -> 0.019251948 | F43: =-'Annual Model'!F104/'Annual Model'!F11 -> 0.018844208 | G43: =-'Annual Model'!G104/'Annual Model'!G11 -> 0.022737534 | H43: 0.0235 | I43: 0.022 | J43: 0.02 | K43: 0.02 | L43: 0.02
B44: Proceeds from Sale of Property and Other Long-Term Assets % Rev | C44: ='Annual Model'!C105/'Annual Model'!C11 -> 0.0022592449 | D44: ='Annual Model'!D105/'Annual Model'!D11 -> 0.0010044979 | E44: ='Annual Model'!E105/'Annual Model'!E11 -> 0.001174026 | F44: ='Annual Model'!F105/'Annual Model'!F11 -> 0.00046363552 | G44: ='Annual Model'!G105/'Annual Model'!G11 -> 0.00061358927 | H44: 0.0005 | I44: 0.0005 | J44: 0.0005 | K44: 0.0005 | L44: 0.0005
B45: Proceeds from Sale of Business | C45: ='Annual Model'!C106 -> 0 | D45: ='Annual Model'!D106 -> 0 | E45: ='Annual Model'!E106 -> 0 | F45: ='Annual Model'!F106 -> 491 | G45: ='Annual Model'!G106 -> 100 | H45: 0 | I45: 0 | J45: 0 | K45: 0 | L45: 0
B46: Other - Net | C46: ='Annual Model'!C107 -> 0 | D46: ='Annual Model'!D107 -> -25 | E46: ='Annual Model'!E107 -> -134 | F46: ='Annual Model'!F107 -> -1 | G46: ='Annual Model'!G107 -> -27 | H46: -10 | I46: -10 | J46: -10 | K46: -10 | L46: -10
B48: Proceeds from Issuance of Common Stock Under Share-Based Payment Plans % Net Income | C48: ='Annual Model'!C114/'Annual Model'!C23 -> 0.027563653 | D48: ='Annual Model'!D114/'Annual Model'!D23 -> 0.0260497 | E48: ='Annual Model'!E114/'Annual Model'!E23 -> 0.015636105 | F48: ='Annual Model'!F114/'Annual Model'!F23 -> 0.023458133 | G48: ='Annual Model'!G114/'Annual Model'!G23 -> 0.018250065 | H48: 0.0215 | I48: 0.0215 | J48: 0.0215 | K48: 0.0215 | L48: 0.0215
B49: Cash Dividend Payments | C49: ='Annual Model'!C115 -> -1618 | D49: ='Annual Model'!D115 -> -1704 | E49: ='Annual Model'!E115 -> -1984 | F49: ='Annual Model'!F115 -> -2370 | G49: ='Annual Model'!G115 -> -2531 | H49: =-H50*'Annual Model'!H28 -> -2524.2354 | I49: =-I50*'Annual Model'!I28 -> -2635.1909 | J49: =-J50*'Annual Model'!J28 -> -2706.868 | K49: =-K50*'Annual Model'!K28 -> -2797.4343 | L49: =-L50*'Annual Model'!L28 -> -2856.3276
B50: Price per Share ($) | C50: =-C49/'Annual Model'!C28 -> 2.0749404 | D50: =-D49/'Annual Model'!D28 -> 2.2690797 | E50: =-E49/'Annual Model'!E28 -> 2.8366359 | F50: =-F49/'Annual Model'!F28 -> 3.7554762 | G50: =-G49/'Annual Model'!G28 -> 4.3340836 | H50: 4.55 | I50: 5 | J50: 5.35 | K50: 5.7 | L50: 6
B51: Dividend Growth (%) | D51: =D50/C50-1 -> 0.093563774 | E51: =E50/D50-1 -> 0.25012615 | F51: =F50/E50-1 -> 0.32391901 | G51: =G50/F50-1 -> 0.15407033 | H51: =H50/G50-1 -> 0.049818233 | I51: =I50/H50-1 -> 0.098901099 | J51: =J50/I50-1 -> 0.07 | K51: =K50/J50-1 -> 0.065420561 | L51: =L50/K50-1 -> 0.052631579
B52: Repurchases of Common Stock | C52: ='Annual Model'!C116 -> -4313 | D52: ='Annual Model'!D116 -> -4971 | E52: ='Annual Model'!E116 -> -13012 | F52: ='Annual Model'!F116 -> -14124 | G52: ='Annual Model'!G116 -> -6138 | H52: -5000 | I52: -5000 | J52: -5000 | K52: -5000 | L52: -5000
...

Sheet Annual Model
B1: Lowe's (NYSE: LOW)
B2: Annual Model & Supporting Schedules
B6: Period End | C6: 43861 | D6: 44225 | E6: 44589 | F6: 44960 | G6: 45324
B7: USD Millions (Expect per Share Data) | C7: 2020A | D7: 2021A | E7: 2022A | F7: 2023A | G7: 2024A | H7: 2025E | I7: 2026E | J7: 2027E | K7: 2028E | L7: 2029E
B10: Income Statement
B11: Net Sales | C11: 72148 | D11: 89597 | E11: 96250 | F11: 97059 | G11: 86377 | H11: =G11*(1+Assumptions!H11) -> 84001.633 | I11: =H11*(1+Assumptions!I11) -> 85261.657 | J11: =I11*(1+Assumptions!J11) -> 88075.292 | K11: =J11*(1+Assumptions!K11) -> 91598.303 | L11: =K11*(1+Assumptions!L11) -> 95262.235
B12: Cost of Sales | C12: 49205 | D12: 60025 | E12: 64194 | F12: 64802 | G12: 57533 | H12: =H11*Assumptions!H12 -> 55777.084 | I12: =I11*Assumptions!I12 -> 56571.109 | J12: =J11*Assumptions!J12 -> 58393.918 | K12: =K11*Assumptions!K12 -> 60683.876 | L12: =L11*Assumptions!L12 -> 63111.231
B13: Gross Profit | C13: =C11-C12 -> 22943 | D13: =D11-D12 -> 29572 | E13: =E11-E12 -> 32056 | F13: =F11-F12 -> 32257 | G13: =G11-G12 -> 28844 | H13: =H11-H12 -> 28224.549 | I13: =I11-I12 -> 28690.548 | J13: =J11-J12 -> 29681.373 | ... L13: =L11-L12 -> 32151.004
B14: Operating Expenses
B15: Selling, General, and Administrative | C15: 15367 | D15: 18526 | E15: 18301 | F15: 20332 | G15: 15570 | H15: =H11*Assumptions!H13 -> 16800.327 | I15: =I11*Assumptions!I13 -> 17052.331 | J15: =J11*Assumptions!J13 -> 17615.058 | K15: =K11*Assumptions!K13 -> 18319.661 | L15: =L11*Assumptions!L13 -> 19052.447
B16: Depreciation & Amortization | C16: 1262 | D16: 1399 | E16: 1662 | F16: 1766 | G16: 1717 | H16: =H149 -> 1683.7797 | I16: =I149 -> 1758.81 | J16: =J149 -> 1829.2702 | K16: =K149 -> 1902.5489 | L16: =L149 -> 1978.7586
B17: Operating Income (EBIT) | C17: =C13-C15-C16 -> 6314 | D17: =D13-D15-D16 -> 9647 | E17: =E13-E15-E16 -> 12093 | F17: =F13-F15-F16 -> 10159 | G17: =G13-G15-G16 -> 11557 | H17: =H13-H15-H16 -> 9740.4423 | I17: =I13-I15-I16 -> 9879.4062 | J17: =J13-J15-J16 -> 10237.045 | ... L17: =L13-L15-L16 -> 11119.799
B18: Interest - Net | C18: 691 | D18: 848 | E18: 885 | F18: 1123 | G18: 1382 | H18: =Assumptions!H20 -> 1361.27 | I18: =Assumptions!I20 -> 1317.0287 | J18: =Assumptions!J20 -> 1277.5179 | K18: =Assumptions!K20 -> 1245.5799 | L18: =Assumptions!L20 -> 1214.4404
B19: Loss on Extinguishment of Debt | C19: 0 | D19: 1060 | E19: 0 | F19: 0 | G19: 0 | H19: =Assumptions!H14 -> 0 | I19: =Assumptions!I14 -> 0 | J19: =Assumptions!J14 -> 0 | K19: =Assumptions!K14 -> 0 | L19: =Assumptions!L14 -> 0
B20: Pre-Tax Earnings (EBT) | C20: =C17-C18-C19 -> 5623 | D20: =D17-D18-D19 -> 7739 | E20: =E17-E18-E19 -> 11208 | F20: =F17-F18-F19 -> 9036 | G20: =G17-G18-G19 -> 10175 | H20: =H17-H18-H19 -> 8379.1723 | I20: =I17-I18-I19 -> 8562.3775 | J20: =J17-J18-J19 -> 8959.5269 | ... L20: =L17-L18-L19 -> 9905.3583
B21: Income Tax Provision | C21: 1342 | D21: 1904 | E21: 2766 | F21: 2599 | G21: 2449 | H21: =H20*H22 -> 2111.2037 | I21: =I20*I22 -> 2157.3638 | J21: =J20*J22 -> 2257.4289 | K21: =K20*K22 -> 2380.1607 | L21: =L20*L22 -> 2495.7392
B22: Tax Rate (%) | C22: =C21/C20 -> 0.23866264 | D22: =D21/D20 -> 0.24602662 | E22: =E21/E20 -> 0.24678801 | F22: =F21/F20 -> 0.28762727 | G22: =G21/G20 -> 0.24068796 | H22: =Assumptions!H15 -> 0.2519585 | I22: =Assumptions!I15 -> 0.2519585 | J22: =Assumptions!J15 -> 0.2519585 | K22: =Assumptions!K15 -> 0.2519585 | L22: =Assumptions!L15 -> 0.2519585
B23: Net Income | C23: =C20-C21 -> 4281 | D23: =D20-D21 -> 5835 | E23: =E20-E21 -> 8442 | F23: =F20-F21 -> 6437 | G23: =G20-G21 -> 7726 | H23: =H20-H21 -> 6267.9686 | I23: =I20-I21 -> 6405.0137 | J23: =J20-J21 -> 6702.0979 | ... L23: =L20-L21 -> 7409.6191
B24: Earnings per Share
B25: Earnings per Share (Basic) | C25: 5.49 | D25: 7.77 | E25: 12.07 | F25: 10.2 | G25: 13.23 | H25: =H23/H28 -> 11.298176 | I25: =I23/I28 -> 12.152846 | J25: =J23/J28 -> 13.246388 | K25: =K23/K28 -> 14.398522 | L25: =L23/L28 -> 15.564641
B26: Earnings per Share (Diluted) | C26: 5.49 | D26: 7.75 | E26: 12.04 | F26: 10.17 | G26: 13.2 | H26: =H23/H29 -> 11.272557 | I26: =I23/I29 -> 12.125288 | J26: =J23/J29 -> 13.216351 | K26: =K23/K29 -> 14.365873 | L26: =L23/L29 -> 15.529347
B27: Shares Used in Computing EPS
B28: Average Shares Outstanding - Basic | C28: =C23/C25 -> 779.78142 | D28: =D23/D25 -> 750.96525 | E28: =E23/E25 -> 699.42005 | F28: =F23/F25 -> 631.07843 | G28: =G23/G25 -> 583.97581 | H28: =Assumptions!H16 -> 554.77702 | I28: =Assumptions!I16 -> 527.03817 | J28: =Assumptions!J16 -> 505.95664 | K28: =Assumptions!K16 -> 490.77794 | L28: =Assumptions!L16 -> 476.05461
B29: Average Shares Outstanding - Diluted | C29: =C23/C26 -> 779.78142 | D29: =D23/D26 -> 752.90323 | E29: =E23/E26 -> 701.16279 | F29: =F23/F26 -> 632.94002 | G29: =G23/G26 -> 585.30303 | H29: =Assumptions!H18 -> 556.03788 | I29: =Assumptions!I18 -> 528.23598 | J29: =Assumptions!J18 -> 507.10655 | K29: =Assumptions!K18 -> 491.89335 | L29: =Assumptions!L18 -> 477.13655
B31: EBITDA | C31: =C17+C83 -> 7724 | D31: =D17+D83 -> 11241 | E31: =E17+E83 -> 13975 | F31: =F17+F83 -> 12140 | G31: =G17+G83 -> 13480 | H31: =H17+H83 -> 11424.222 | I31: =I17+I83 -> 11638.216 | J31: =J17+J83 -> 12066.315 | ... L31: =L17+L83 -> 13098.557
B33: Balance Sheet
B34: Current Assets
B35: Cash & Cash Equivalents | C35: 716 | D35: 4690 | E35: 1133 | F35: 1348 | G35: 921 | H35: =G35+H122+H123 -> 1011.0884 | I35: =H35+I122+I123 -> 600.38649 | J35: =I35+J122+J123 -> 539.78755 | K35: =J35+K122+K123 -> 743.6357 | L35: =K35+L122+L123 -> 1240.7039
B36: Short-Term Investments | C36: 160 | D36: 506 | E36: 271 | F36: 384 | G36: 307 | H36: =G36 -> 307 | I36: =H36 -> 307 | J36: =I36 -> 307 | K36: =J36 -> 307 | L36: =K36 -> 307
B37: Merchandise Inventory - Net | C37: 13179 | D37: 16193 | E37: 17605 | F37: 18532 | G37: 16894 | H37: =G37-H92 -> 17172.397 | I37: =H37-I92 -> 17420.802 | J37: =I37-J92 -> 17982.127 | K37: =J37-K92 -> 18687.309 | L37: =K37-L92 -> 19434.801
B38: Other Current Assets | C38: 1263 | D38: 937 | E38: 1051 | F38: 1178 | G38: 949 | H38: =G38-H93 -> 1034.2538 | I38: =H38-I93 -> 1051.1711 | J38: =I38-J93 -> 1085.8598 | K38: =J38-K93 -> 1129.2942 | L38: =K38-L93 -> 1174.4659
B39: Total Current Assets | C39: =SUM(C35:C38) -> 15318 | D39: =SUM(D35:D38) -> 22326 | E39: =SUM(E35:E38) -> 20060 | F39: =SUM(F35:F38) -> 21442 | G39: =SUM(G35:G38) -> 19071 | H39: =SUM(H35:H38) -> 19524.739 | I39: =SUM(I35:I38) -> 19379.36 | J39: =SUM(J35:J38) -> 19914.775 | ... L39: =SUM(L35:L38) -> 22156.971
B40: Property, Less Accumulated Depreciation | C40: 18769 | D40: 19155 | E40: 19071 | F40: 17567 | G40: 17653 | H40: =G40-H83-H104-H105-H106 -> 17901.258 | I40: =H40-I83-I104-I105-I106 -> 17975.573 | J40: =I40-J83-J104-J105-J106 -> 17863.771 | K40: =J40-K83-K104-K105-K106 -> 17747.39 | L40: =K40-L83-L104-L105-L106 -> 17626.244
B41: Operating Lease ROU Assets | C41: 3891 | D41: 3832 | E41: 4108 | F41: 3518 | G41: 3733 | H41: =G41 -> 3733 | I41: =H41 -> 3733 | J41: =I41 -> 3733 | K41: =J41 -> 3733 | L41: =K41 -> 3733
B42: Long-Term Investments | C42: 372 | D42: 200 | E42: 199 | F42: 121 | G42: 252 | H42: =G42-H102-H103 -> 269.73168 | I42: =H42-I102-I103 -> 287.72934 | J42: =I42-J102-J103 -> 306.32092 | K42: =J42-K102-K103 -> 325.65616 | L42: =K42-L102-L103 -> 345.76481
B43: Deferred Income Taxes - Net | C43: 216 | D43: 340 | E43: 164 | F43: 250 | G43: 248 | H43: =G43-H85 -> 239.53769 | I43: =H43-I85 -> 189.83451 | J43: =I43-J85 -> 162.74948 | K43: =J43-K85 -> 156.95156 | L43: =K43-L85 -> 171.15072
B44: Other Assets | C44: 905 | D44: 882 | E44: 1038 | F44: 810 | G44: 838 | H44: =G44-H107 -> 848 | I44: =H44-I107 -> 858 | J44: =I44-J107 -> 868 | K44: =J44-K107 -> 878 | L44: =K44-L107 -> 888
B45: Total Noncurrent Assets | C45: =SUM(C40:C44) -> 24153 | D45: =SUM(D40:D44) -> 24409 | E45: =SUM(E40:E44) -> 24580 | F45: =SUM(F40:F44) -> 22266 | G45: =SUM(G40:G44) -> 22724 | H45: =SUM(H40:H44) -> 22991.527 | I45: =SUM(I40:I44) -> 23044.137 | J45: =SUM(J40:J44) -> 22933.842 | ... L45: =SUM(L40:L44) -> 22764.16
B46: Total Assets | C46: =C39+C45 -> 39471 | D46: =D39+D45 -> 46735 | E46: =E39+E45 -> 44640 | F46: =F39+F45 -> 43708 | G46: =G39+G45 -> 41795 | H46: =H39+H45 -> 42516.266 | I46: =I39+I45 -> 42423.497 | J46: =J39+J45 -> 42848.616 | ... L46: =L39+L45 -> 44921.131
B48: Current Liabilities
...

Sheet DCF
B1: Lowe's (NYSE: LOW)
B2: Discounted Cash Flow Analysis
B6: Period End | C6: 43861 | D6: 44225 | E6: 44589 | F6: 44960 | G6: 45324
B7: USD Millions (Expect per Share Data) | C7: 2020A | D7: 2021A | E7: 2022A | F7: 2023A | G7: 2024A | H7: 2025E | I7: 2026E | J7: 2027E | K7: 2028E | L7: 2029E
B10: DCF Analysis | N10: Multiples Method | Q10: Gordon Growth
B11: Revenue | C11: ='Annual Model'!C11 -> 72148 | D11: ='Annual Model'!D11 -> 89597 | E11: ='Annual Model'!E11 -> 96250 | F11: ='Annual Model'!F11 -> 97059 | G11: ='Annual Model'!G11 -> 86377 | H11: ='Annual Model'!H11 -> 84001.633 | I11: ='Annual Model'!I11 -> 85261.657 | J11: ='Annual Model'!J11 -> 88075.292 | ... L11: ='Annual Model'!L11 -> 95262.235 | N11: Sum of PV UFCF | O11: =SUM(H37:L37) -> 30155.804 | Q11: Sum of PV UFCF | R11: =SUM(H37:L37) -> 30155.804
B12: Cost of Sales | C12: ='Annual Model'!C12 -> 49205 | D12: ='Annual Model'!D12 -> 60025 | E12: ='Annual Model'!E12 -> 64194 | F12: ='Annual Model'!F12 -> 64802 | G12: ='Annual Model'!G12 -> 57533 | H12: ='Annual Model'!H12 -> 55777.084 | I12: ='Annual Model'!I12 -> 56571.109 | J12: ='Annual Model'!J12 -> 58393.918 | ... L12: ='Annual Model'!L12 -> 63111.231 | N12: Exit Year EBITDA | O12: =L16 -> 13098.557 | Q12: Terminal Year UFCF | R12: =L31 -> 8243.7961
B13: Gross Profit | C13: =C11-C12 -> 22943 | D13: =D11-D12 -> 29572 | E13: =E11-E12 -> 32056 | F13: =F11-F12 -> 32257 | G13: =G11-G12 -> 28844 | H13: =H11-H12 -> 28224.549 | I13: =I11-I12 -> 28690.548 | J13: =J11-J12 -> 29681.373 | ... L13: =L11-L12 -> 32151.004 | N13: EBITDA Multiple | O13: =WACC!F19/DCF!O12 -> 14.602374 | Q13: Perpetuity Growth Rate | R13: 0.02
B14: Selling, General, and Administrative | C14: ='Annual Model'!C15 -> 15367 | D14: ='Annual Model'!D15 -> 18526 | E14: ='Annual Model'!E15 -> 18301 | F14: ='Annual Model'!F15 -> 20332 | G14: ='Annual Model'!G15 -> 15570 | H14: ='Annual Model'!H15 -> 16800.327 | I14: ='Annual Model'!I15 -> 17052.331 | J14: ='Annual Model'!J15 -> 17615.058 | ... L14: ='Annual Model'!L15 -> 19052.447 | N14: Terminal Value | O14: =O12*O13 -> 191270.04 | Q14: Terminal Value | R14: =(R12*(1+R13)/(L35-R13)) -> 123067.85
B15: SG&A % Rev | C15: =C14/C11 -> 0.21299274 | D15: =D14/D11 -> 0.20677032 | E15: =E14/E11 -> 0.19014026 | F15: =F14/F11 -> 0.20948083 | G15: =G14/G11 -> 0.18025632 | H15: =H14/H11 -> 0.2 | I15: =I14/I11 -> 0.2 | J15: =J14/J11 -> 0.2 | ... L15: =L14/L11 -> 0.2 | N15: PV of Terminal Value | O15: =O14/(1+L35)^L34 -> 125271.69 | Q15: PV of Terminal Value | R15: =R14/(1+L35)^L34 -> 80602.89
B16: EBITDA | C16: =C20+C18 -> 7576 | D16: =D20+D18 -> 11046 | E16: =E20+E18 -> 13755 | F16: =F20+F18 -> 11925 | G16: =G20+G18 -> 13274 | H16: =H20+H18 -> 11424.222 | I16: =I20+I18 -> 11638.216 | J16: =J20+J18 -> 12066.315 | ... L16: =L20+L18 -> 13098.557 | N16: Enterprise Value | O16: =O11+O15 -> 155427.49 | Q16: Enterprise Value | R16: =R11+R15 -> 110758.69
B17: EBITDA Margin (%) | C17: =C16/C11 -> 0.10500638 | D17: =D16/D11 -> 0.12328538 | E17: =E16/E11 -> 0.14290909 | F17: =F16/F11 -> 0.12286341 | G17: =G16/G11 -> 0.15367517 | H17: =H16/H11 -> 0.136 | I17: =I16/I11 -> 0.1365 | J17: =J16/J11 -> 0.137 | ... L17: =L16/L11 -> 0.1375 | N17: (+) Cash & Investments | O17: 3271 | Q17: (+) Cash & Investments | R17: 3271
B18: Depreciation & Amortization | C18: ='Annual Model'!C83 -> 1410 | D18: ='Annual Model'!D83 -> 1594 | E18: ='Annual Model'!E83 -> 1882 | F18: ='Annual Model'!F83 -> 1981 | G18: ='Annual Model'!G83 -> 1923 | H18: ='Annual Model'!H83 -> 1683.7797 | I18: ='Annual Model'!I83 -> 1758.81 | J18: ='Annual Model'!J83 -> 1829.2702 | ... L18: ='Annual Model'!L83 -> 1978.7586 | N18: (+) Net Operating Losses | O18: 332 | Q18: (+) Net Operating Losses | R18: 332
B19: D&A % Rev | C19: =C18/C11 -> 0.019543161 | D19: =D18/D11 -> 0.017790774 | E19: =E18/E11 -> 0.019553247 | F19: =F18/F11 -> 0.020410266 | G19: =G18/G11 -> 0.022262871 | H19: =H18/H11 -> 0.020044607 | I19: =I18/I11 -> 0.020628381 | J19: =J18/J11 -> 0.020769391 | ... L19: =L18/L11 -> 0.020771701 | N19: (-) Total Debt & Finance Leases | O19: =-32906-425 -> -33331 | Q19: (-) Total Debt & Finance Leases | R19: =-32906-425 -> -33331
B20: EBIT | C20: =C13-C14-C18 -> 6166 | D20: =D13-D14-D18 -> 9452 | E20: =E13-E14-E18 -> 11873 | F20: =F13-F14-F18 -> 9944 | G20: =G13-G14-G18 -> 11351 | H20: =H13-H14-H18 -> 9740.4423 | I20: =I13-I14-I18 -> 9879.4062 | J20: =J13-J14-J18 -> 10237.045 | ... L20: =L13-L14-L18 -> 11119.799 | N20: (-) Preferred Stock | O20: 0 | Q20: (-) Preferred Stock | R20: 0
B21: EBIT Growth (%) | D21: =D20/C20-1 -> 0.53292248 | E21: =E20/D20-1 -> 0.25613627 | F21: =F20/E20-1 -> -0.16246947 | G21: =G20/F20-1 -> 0.14149236 | H21: =H20/G20-1 -> -0.14188686 | I21: =I20/H20-1 -> 0.014266693 | J21: =J20/I20-1 -> 0.036200409 | K21: =K20/J20-1 -> 0.044463331 | L21: =L20/K20-1 -> 0.039989915 | N21: (-) Operating Leases | O21: -3771 | Q21: (-) Operating Leases | R21: -3771
B22: EBIT Margin (%) | C22: =C20/C11 -> 0.085463215 | D22: =D20/D11 -> 0.1054946 | E22: =E20/E11 -> 0.12335584 | F22: =F20/F11 -> 0.10245315 | G22: =G20/G11 -> 0.1314123 | H22: =H20/H11 -> 0.11595539 | I22: =I20/I11 -> 0.11587162 | J22: =J20/J11 -> 0.11623061 | ... L22: =L20/L11 -> 0.1167283 | N22: (-) Noncontrolling Interests | O22: 0 | Q22: (-) Noncontrolling Interests | R22: 0
B23: Income Tax Expense | C23: =-C20*C24 -> -1471.5938 | D23: =-D20*D24 -> -2325.4436 | E23: =-E20*E24 -> -2930.114 | F23: =-F20*F24 -> -2860.1656 | G23: =-G20*G24 -> -2732.049 | H23: =-H20*H24 -> -2454.1872 | I23: =-I20*I24 -> -2489.2004 | J23: =-J20*J24 -> -2579.3104 | ... L23: =-L20*L24 -> -2801.7278 | N23: (-) Unfunded Pensions | O23: 0 | Q23: (-) Unfunded Pensions | R23: 0
B24: Tax Rate (%) | C24: ='Annual Model'!C22 -> 0.23866264 | D24: ='Annual Model'!D22 -> 0.24602662 | E24: ='Annual Model'!E22 -> 0.24678801 | F24: ='Annual Model'!F22 -> 0.28762727 | G24: ='Annual Model'!G22 -> 0.24068796 | H24: ='Annual Model'!H22 -> 0.2519585 | I24: ='Annual Model'!I22 -> 0.2519585 | J24: ='Annual Model'!J22 -> 0.2519585 | ... L24: ='Annual Model'!L22 -> 0.2519585 | N24: Implied Equity Value | O24: =SUM(O16:O23) -> 121928.49 | Q24: Implied Equity Value | R24: =SUM(R16:R23) -> 77259.695
B25: NOPAT | C25: =C20+C23 -> 4694.4062 | D25: =D20+D23 -> 7126.5564 | E25: =E20+E23 -> 8942.886 | F25: =F20+F23 -> 7083.8344 | G25: =G20+G23 -> 8618.951 | H25: =H20+H23 -> 7286.2551 | I25: =I20+I23 -> 7390.2059 | J25: =J20+J23 -> 7657.7343 | ... L25: =L20+L23 -> 8318.0709 | N25: Fully Diluted Shares Outstanding | O25: ='Annual Model'!G29 -> 585.30303 | Q25: Fully Diluted Shares Outstanding | R25: ='Annual Model'!G29 -> 585.30303
B26: Add: D&A | C26: ='Annual Model'!C83 -> 1410 | D26: ='Annual Model'!D83 -> 1594 | E26: ='Annual Model'!E83 -> 1882 | F26: ='Annual Model'!F83 -> 1981 | G26: ='Annual Model'!G83 -> 1923 | H26: ='Annual Model'!H83 -> 1683.7797 | I26: ='Annual Model'!I83 -> 1758.81 | J26: ='Annual Model'!J83 -> 1829.2702 | ... L26: ='Annual Model'!L83 -> 1978.7586 | N26: Implied Share Price | O26: =O24/O25 -> 208.31687 | Q26: Implied Share Price | R26: =R24/R25 -> 131.99948
B27: Less: CAPEX | C27: ='Annual Model'!C104 -> -1484 | D27: ='Annual Model'!D104 -> -1791 | E27: ='Annual Model'!E104 -> -1853 | F27: ='Annual Model'!F104 -> -1829 | G27: ='Annual Model'!G104 -> -1964 | H27: ='Annual Model'!H104 -> -1974.0384 | I27: ='Annual Model'!I104 -> -1875.7565 | J27: ='Annual Model'!J104 -> -1761.5058 | ... L27: ='Annual Model'!L104 -> -1905.2447
B28: CAPEX % Rev | C28: =-C27/C11 -> 0.020568831 | D28: =-D27/D11 -> 0.019989509 | E28: =-E27/E11 -> 0.019251948 | F28: =-F27/F11 -> 0.018844208 | G28: =-G27/G11 -> 0.022737534 | H28: =-H27/H11 -> 0.0235 | I28: =-I27/I11 -> 0.022 | J28: =-J27/J11 -> 0.02 | ... L28: =-L27/L11 -> 0.02 | N28: % EV from TV | O28: =O16/O14 -> 0.81260763 | Q28: % EV from TV | R28: =R16/R14 -> 0.89998071
B29: Less: Change in Net Working Capital | C29: ='Annual Model'!C98 -> -2255 | D29: ='Annual Model'!D98 -> 1895 | E29: ='Annual Model'!E98 -> -1127 | F29: ='Annual Model'!F98 -> -2882 | G29: ='Annual Model'!G98 -> -2228 | H29: ='Annual Model'!H98 -> 715.00468 | I29: ='Annual Model'!I98 -> -39.95549 | J29: ='Annual Model'!J98 -> -107.36652 | ... L29: ='Annual Model'!L98 -> -147.7888 | Q29: Implied Multiple | R29: =R14/L16 -> 9.3955274
B30: Change in NWC % Rev | C30: =C29/C11 -> -0.031255198 | D30: =D29/D11 -> 0.021150262 | E30: =E29/E11 -> -0.011709091 | F30: =F29/F11 -> -0.029693279 | G30: =G29/G11 -> -0.025793903 | H30: =H29/H11 -> 0.008511795 | I30: =I29/I11 -> -0.00046862202 | J30: =J29/J11 -> -0.0012190311 | ... L30: =L29/L11 -> -0.0015513892
B31: UFCF | C31: =C25+C26+C27+C29 -> 2365.4062 | D31: =D25+D26+D27+D29 -> 8824.5564 | E31: =E25+E26+E27+E29 -> 7844.886 | F31: =F25+F26+F27+F29 -> 4353.8344 | G31: =G25+G26+G27+G29 -> 6349.951 | H31: =H25+H26+H27+H29 -> 7711.0011 | I31: =I25+I26+I27+I29 -> 7233.3039 | J31: =J25+J26+J27+J29 -> 7618.1322 | ... L31: =L25+L26+L27+L29 -> 8243.7961 | N31: Current Price | O31: 268.42 | Q31: Current Price | R31: 268.42
B32: Growth % | D32: =D31/C31-1 -> 2.7306727 | E32: =E31/D31-1 -> -0.11101639 | F32: =F31/E31-1 -> -0.44500985 | G32: =G31/F31-1 -> 0.45847323 | H32: =H31/G31-1 -> 0.21434026 | I32: =I31/H31-1 -> -0.061950093 | J32: =J31/I31-1 -> 0.053202286 | K32: =K31/J31-1 -> 0.041347621 | L32: =L31/K31-1 -> 0.039161401 | N32: Dividend Yield | O32: 0.0171 | Q32: Dividend Yield | R32: 0.0171
N33: Implied Return | O33: =((O26-O31)/O31)+O32 -> -0.20681451 | Q33: Implied Return | R33: =((R26-R31)/R31)+R32 -> -0.49113531
B34: Discount Period | H34: 1 | I34: 2 | J34: 3 | K34: 4 | L34: 5
B35: WACC | H35: =WACC!C15 -> 0.088325494 | I35: =H35 -> 0.088325494 | J35: =I35 -> 0.088325494 | K35: =J35 -> 0.088325494 | L35: =K35 -> 0.088325494
B36: Discount Factor | H36: =1/(1+H35)^H34 -> 0.91884276 | I36: =1/(1+I35)^I34 -> 0.84427202 | J36: =1/(1+J35)^J34 -> 0.77575323 | K36: =1/(1+K35)^K34 -> 0.71279524 | L36: =1/(1+L35)^L34 -> 0.65494674
B37: PV of UFCF | H37: =H31*H36 -> 7085.1975 | I37: =I31*I36 -> 6106.8761 | J37: =J31*J36 -> 5909.7906 | K37: =K31*K36 -> 5654.6929 | L37: =L31*L36 -> 5399.2474

Sheet WACC
B1: Lowe's (NYSE: LOW)
B2: WACC Analysis
B6: Wacc Analysis | E6: Market Capitalization | H6: Capital Structure
B7: 30 Year US Treasury | C7: 0.0468 | E7: Share Price | F7: 268.42 | H7: Unit | I7: Value | J7: %
B8: Market Risk Premium | C8: 0.046 | E8: Common Shares Outstanding | F8: ='Annual Model'!G28 -> 583.97581 | H8: Total Debt | I8: 32906 | J8: =I8/I12 -> 0.7103292
B9: Beta | C9: 1.1 | E9: Market Capitalization | F9: =F7*F8 -> 156750.79 | H9: Total Common Equity | I9: 13419 | J9: =I9/I12 -> 0.2896708 | K9: actually a deficit on BS - just changed to positive for calc
B10: Cost of Equity | C10: =C7+(C8*C9) -> 0.0974 | E10: Diluted Shares Outstanding | F10: ='Annual Model'!G29 -> 585.30303 | H10: Total Preferred Equity | I10: 0 | J10: =I10/I12 -> 0
B11: % of Capital Structure | C11: =F11/(F11+I8) -> 0.82682241 | E11: Diluted Market Capitalization | F11: =F7*F10 -> 157107.04 | H11: Total Noncontrolling Interests | I11: 0 | J11: =I11/I12 -> 0
B12: Cost of Debt | C12: 0.045 | E12: (-) Cash & Investments | F12: -3271 | H12: Total | I12: =SUM(I8:I11) -> 46325 | J12: =SUM(J8:J11) -> 1
B13: % of Capital Structure | C13: =I8/(F11+I8) -> 0.17317759 | E13: (-) Net Operating Losses | F13: 332
E14: (+) Total Debt & Finance Leases | F14: =32906+425 -> 33331
B15: WACC | C15: =(C10*C11)+(C12*C13) -> 0.088325494 | E15: (+) Preferred Stock | F15: 0
E16: (+) Operating Leases | F16: 3771
E17: (+) Noncontrolling Interests | F17: 0
E18: (+) Unfunded Pensions | F18: 0
E19: Enterprise Value (TEV) | F19: =SUM(F11:F18) -> 191270.04

Sheet Comps
B1: Lowe's (NYSE: LOW)
B2: Public Comps Analysis
B5: Values in Million, Except Per Share Data
G9: Capitalization | N9: Revenue | Q9: EBITDA | T9: Net Income | W9: Growth Projections
B10: Company | C10: Ticker | D10: Share Price | E10: FDSO | F10: Market Cap | G10: Beta | H10: Tax Rate | I10: Cash | J10: Debt | K10: Preferred | L10: Other & NCI | M10: EV | N10: LTM | O10: 2025E | P10: 2026E | Q10: LTM | R10: 2025E | S10: 2026E | T10: LTM | U10: 2025E | V10: 2026E | W10: Revenue | X10: EBITDA
B11: Home Depot | C11: HD | D11: 424.87 | E11: 1002 | F11: =D11*E11 -> 425719.74 | G11: 1.01 | H11: 0.24 | I11: 1531 | J11: =44111+777 -> 44888 | K11: 0 | L11: 0 | M11: =F11+I11+J11+K11+L11 -> 472138.74 | N11: 154596 | O11: 158391 | P11: 164060 | Q11: 24984 | R11: 25204 | S11: 26088 | T11: 14610 | U11: 14792 | V11: 15455 | W11: =P11/O11-1 -> 0.035791175 | X11: =S11/R11-1 -> 0.035073798
B12: Target | C12: TGT | D12: 141.06 | E12: 461.5 | F12: =D12*E12 -> 65099.19 | G12: 1.24 | H12: 0.22 | I12: 3433 | J12: =16038 -> 16038 | K12: 0 | L12: 0 | M12: =F12+I12+J12+K12+L12 -> 84570.19 | N12: 107570 | O12: 106212 | P12: 109126 | Q12: 9013 | R12: 8352 | S12: 8711 | T12: 4370 | U12: 4000 | V12: 4207 | W12: =P12/O12-1 -> 0.027435695 | X12: =S12/R12-1 -> 0.042983716
B13: Walmart | C13: WMT | D13: 97.29 | E13: 8082 | F13: =D13*E13 -> 786297.78 | G13: 0.52 | H13: 0.227 | I13: 10049 | J13: =39579+1071 -> 40650 | K13: 0 | L13: -759 | M13: =F13+I13+J13+K13+L13 -> 836237.78 | N13: 673819 | O13: 676620 | P13: 705450 | Q13: 42286 | R13: 42325 | S13: 46130 | T13: 19676 | U13: 19421 | V13: 21994 | W13: =P13/O13-1 -> 0.04260885 | X13: =S13/R13-1 -> 0.089899587
B14: Best Buy | C14: BBY | D14: 86.78 | E14: 216.7 | F14: =D14*E14 -> 18805.226 | G14: 1.49 | H14: 0.2388 | I14: 643 | J14: =1152+13+16 -> 1181 | K14: 0 | L14: 0 | M14: =F14+I14+J14+K14+L14 -> 20629.226 | N14: 42226 | O14: 41276 | P14: 41827 | Q14: 2579 | R14: 2568 | S14: 2677 | T14: 1270 | U14: 1313 | V14: 1372 | W14: =P14/O14-1 -> 0.013349162 | X14: =S14/R14-1 -> 0.042445483
B15: Costco | C15: COST | D15: 958.67 | E15: 444.75 | F15: =D15*E15 -> 426368.48 | G15: 0.79 | H15: 0.2436 | I15: 9906 | J15: =5919 -> 5919 | K15: 0 | L15: 0 | M15: =F15+I15+J15+K15+L15 -> 442193.48 | N15: 258805 | O15: 272619 | P15: 291802 | Q15: 12392 | R15: 12812 | S15: 14012 | T15: 7576 | U15: 8102 | V15: 8851 | W15: =P15/O15-1 -> 0.070365602 | X15: =S15/R15-1 -> 0.093662192
B17: Maximum | D17: =MAX(D11:D15) -> 958.67 | F17: =MAX(F11:F15) -> 786297.78 | M17: =MAX(M11:M15) -> 836237.78 | N17: =MAX(N11:N15) -> 673819 | O17: =MAX(O11:O15) -> 676620 | P17: =MAX(P11:P15) -> 705450 | Q17: =MAX(Q11:Q15) -> 42286 | R17: =MAX(R11:R15) -> 42325 | S17: =MAX(S11:S15) -> 46130 | T17: =MAX(T11:T15) -> 19676 | ... X17: =MAX(X11:X15) -> 0.093662192
B18: 75th Percentile | D18: =_xlfn.QUARTILE.EXC(D11:D15,3) -> 691.77 | F18: =_xlfn.QUARTILE.EXC(F11:F15,3) -> 606333.13 | M18: =_xlfn.QUARTILE.EXC(M11:M15,3) -> 654188.26 | N18: =_xlfn.QUARTILE.EXC(N11:N15,3) -> 466312 | O18: =_xlfn.QUARTILE.EXC(O11:O15,3) -> 474619.5 | P18: =_xlfn.QUARTILE.EXC(P11:P15,3) -> 498626 | Q18: =_xlfn.QUARTILE.EXC(Q11:Q15,3) -> 33635 | R18: =_xlfn.QUARTILE.EXC(R11:R15,3) -> 33764.5 | S18: =_xlfn.QUARTILE.EXC(S11:S15,3) -> 36109 | T18: =_xlfn.QUARTILE.EXC(T11:T15,3) -> 17143 | ... X18: =_xlfn.QUARTILE.EXC(X11:X15,3) -> 0.091780889
B19: Median | D19: =MEDIAN(D11:D15) -> 141.06 | F19: =MEDIAN(F11:F15) -> 425719.74 | M19: =MEDIAN(M11:M15) -> 442193.48 | N19: =MEDIAN(N11:N15) -> 154596 | O19: =MEDIAN(O11:O15) -> 158391 | P19: =MEDIAN(P11:P15) -> 164060 | Q19: =MEDIAN(Q11:Q15) -> 12392 | R19: =MEDIAN(R11:R15) -> 12812 | S19: =MEDIAN(S11:S15) -> 14012 | T19: =MEDIAN(T11:T15) -> 7576 | ... X19: =MEDIAN(X11:X15) -> 0.042983716
B20: 25th Percentile | D20: =_xlfn.QUARTILE.EXC(D11:D15,1) -> 92.035 | F20: =_xlfn.QUARTILE.EXC(F11:F15,1) -> 41952.208 | M20: =_xlfn.QUARTILE.EXC(M11:M15,1) -> 52599.708 | N20: =_xlfn.QUARTILE.EXC(N11:N15,1) -> 74898 | O20: =_xlfn.QUARTILE.EXC(O11:O15,1) -> 73744 | P20: =_xlfn.QUARTILE.EXC(P11:P15,1) -> 75476.5 | Q20: =_xlfn.QUARTILE.EXC(Q11:Q15,1) -> 5796 | R20: =_xlfn.QUARTILE.EXC(R11:R15,1) -> 5460 | S20: =_xlfn.QUARTILE.EXC(S11:S15,1) -> 5694 | T20: =_xlfn.QUARTILE.EXC(T11:T15,1) -> 2820 | ... X20: =_xlfn.QUARTILE.EXC(X11:X15,1) -> 0.03875964
B21: Minimum | D21: =MIN(D11:D15) -> 86.78 | F21: =MIN(F11:F15) -> 18805.226 | M21: =MIN(M11:M15) -> 20629.226 | N21: =MIN(N11:N15) -> 42226 | O21: =MIN(O11:O15) -> 41276 | P21: =MIN(P11:P15) -> 41827 | Q21: =MIN(Q11:Q15) -> 2579 | R21: =MIN(R11:R15) -> 2568 | S21: =MIN(S11:S15) -> 2677 | T21: =MIN(T11:T15) -> 1270 | ... X21: =MIN(X11:X15) -> 0.035073798
B24: Lowe's | C24: LOW | D24: 268.42 | E24: 585 | F24: =D24*E24 -> 157025.7 | G24: 1.1 | H24: 0.25 | I24: 3271 | J24: 32906 | K24: 0 | L24: 0 | M24: =F24+I24+J24+K24+L24 -> 193202.7 | N24: 83722 | O24: 83332 | P24: 84678 | Q24: 12428 | R24: 12170 | S24: 12495 | T24: 6853 | U24: 6845 | V24: 7023 | W24: =P24/O24-1 -> 0.016152258 | X24: =S24/R24-1 -> 0.026705012
G31: Capitalization | N31: EV/Rev | Q31: EV/EBITDA | T31: Equity Value/Net Income
B32: Company | C32: Ticker | F32: Market Cap | M32: EV | N32: LTM | O32: 2025E | P32: 2026E | Q32: LTM | R32: 2025E | S32: 2026E | T32: LTM | U32: 2025E | V32: 2026E
B33: Home Depot | C33: HD | F33: =F11 -> 425719.74 | M33: =M11 -> 472138.74 | N33: =IFERROR(IF(OR($M11/N11<0,$M11/N11>=100), "NM", $M11/N11), "N/A") -> 3.0540165 | O33: =IFERROR(IF(OR($M11/O11<0,$M11/O11>=100), "NM", $M11/O11), "N/A") -> 2.9808432 | P33: =IFERROR(IF(OR($M11/P11<0,$M11/P11>=100), "NM", $M11/P11), "N/A") -> 2.8778419 | Q33: =IFERROR(IF(OR($M11/Q11<0,$M11/Q11>=100), "NM", $M11/Q11), "N/A") -> 18.897644 | R33: =IFERROR(IF(OR($M11/R11<0,$M11/R11>=100), "NM", $M11/R11), "N/A") -> 18.732691 | S33: =IFERROR(IF(OR($M11/S11<0,$M11/S11>=100), "NM", $M11/S11), "N/A") -> 18.097928 | T33: =IFERROR(IF(OR($F11/T11<0,$F11/T11>=100), "NM", $F11/T11), "N/A") -> 29.138928 | U33: =IFERROR(IF(OR($F11/U11<0,$F11/U11>=100), "NM", $F11/U11), "N/A") -> 28.780404 | V33: =IFERROR(IF(OR($F11/V11<0,$F11/V11>=100), "NM", $F11/V11), "N/A") -> 27.545761
B34: Target | C34: TGT | F34: =F12 -> 65099.19 | M34: =M12 -> 84570.19 | N34: =IFERROR(IF(OR($M12/N12<0,$M12/N12>=100), "NM", $M12/N12), "N/A") -> 0.78618751 | O34: =IFERROR(IF(OR($M12/O12<0,$M12/O12>=100), "NM", $M12/O12), "N/A") -> 0.7962395 | P34: =IFERROR(IF(OR($M12/P12<0,$M12/P12>=100), "NM", $M12/P12), "N/A") -> 0.77497746 | Q34: =IFERROR(IF(OR($M12/Q12<0,$M12/Q12>=100), "NM", $M12/Q12), "N/A") -> 9.3831344 | R34: =IFERROR(IF(OR($M12/R12<0,$M12/R12>=100), "NM", $M12/R12), "N/A") -> 10.125741 | S34: =IFERROR(IF(OR($M12/S12<0,$M12/S12>=100), "NM", $M12/S12), "N/A") -> 9.7084365 | T34: =IFERROR(IF(OR($F12/T12<0,$F12/T12>=100), "NM", $F12/T12), "N/A") -> 14.89684 | U34: =IFERROR(IF(OR($F12/U12<0,$F12/U12>=100), "NM", $F12/U12), "N/A") -> 16.274798 | V34: =IFERROR(IF(OR($F12/V12<0,$F12/V12>=100), "NM", $F12/V12), "N/A") -> 15.474017
B35: Walmart | C35: WMT | F35: =F13 -> 786297.78 | M35: =M13 -> 836237.78 | N35: =IFERROR(IF(OR($M13/N13<0,$M13/N13>=100), "NM", $M13/N13), "N/A") -> 1.2410421 | O35: =IFERROR(IF(OR($M13/O13<0,$M13/O13>=100), "NM", $M13/O13), "N/A") -> 1.2359046 | P35: =IFERROR(IF(OR($M13/P13<0,$M13/P13>=100), "NM", $M13/P13), "N/A") -> 1.1853962 | Q35: =IFERROR(IF(OR($M13/Q13<0,$M13/Q13>=100), "NM", $M13/Q13), "N/A") -> 19.77576 | R35: =IFERROR(IF(OR($M13/R13<0,$M13/R13>=100), "NM", $M13/R13), "N/A") -> 19.757538 | S35: =IFERROR(IF(OR($M13/S13<0,$M13/S13>=100), "NM", $M13/S13), "N/A") -> 18.127851 | T35: =IFERROR(IF(OR($F13/T13<0,$F13/T13>=100), "NM", $F13/T13), "N/A") -> 39.962278 | U35: =IFERROR(IF(OR($F13/U13<0,$F13/U13>=100), "NM", $F13/U13), "N/A") -> 40.486987 | V35: =IFERROR(IF(OR($F13/V13<0,$F13/V13>=100), "NM", $F13/V13), "N/A") -> 35.750558
B36: Best Buy | C36: BBY | F36: =F14 -> 18805.226 | M36: =M14 -> 20629.226 | N36: =IFERROR(IF(OR($M14/N14<0,$M14/N14>=100), "NM", $M14/N14), "N/A") -> 0.48854322 | O36: =IFERROR(IF(OR($M14/O14<0,$M14/O14>=100), "NM", $M14/O14), "N/A") -> 0.49978743 | P36: =IFERROR(IF(OR($M14/P14<0,$M14/P14>=100), "NM", $M14/P14), "N/A") -> 0.49320358 | Q36: =IFERROR(IF(OR($M14/Q14<0,$M14/Q14>=100), "NM", $M14/Q14), "N/A") -> 7.9989244 | R36: =IFERROR(IF(OR($M14/R14<0,$M14/R14>=100), "NM", $M14/R14), "N/A") -> 8.0331877 | S36: =IFERROR(IF(OR($M14/S14<0,$M14/S14>=100), "NM", $M14/S14), "N/A") -> 7.7060986 | T36: =IFERROR(IF(OR($F14/T14<0,$F14/T14>=100), "NM", $F14/T14), "N/A") -> 14.807265 | U36: =IFERROR(IF(OR($F14/U14<0,$F14/U14>=100), "NM", $F14/U14), "N/A") -> 14.322335 | V36: =IFERROR(IF(OR($F14/V14<0,$F14/V14>=100), "NM", $F14/V14), "N/A") -> 13.706433
B37: Costco | C37: COST | F37: =F15 -> 426368.48 | M37: =M15 -> 442193.48 | N37: =IFERROR(IF(OR($M15/N15<0,$M15/N15>=100), "NM", $M15/N15), "N/A") -> 1.7085971 | O37: =IFERROR(IF(OR($M15/O15<0,$M15/O15>=100), "NM", $M15/O15), "N/A") -> 1.62202 | P37: =IFERROR(IF(OR($M15/P15<0,$M15/P15>=100), "NM", $M15/P15), "N/A") -> 1.5153888 | Q37: =IFERROR(IF(OR($M15/Q15<0,$M15/Q15>=100), "NM", $M15/Q15), "N/A") -> 35.683787 | R37: =IFERROR(IF(OR($M15/R15<0,$M15/R15>=100), "NM", $M15/R15), "N/A") -> 34.514009 | S37: =IFERROR(IF(OR($M15/S15<0,$M15/S15>=100), "NM", $M15/S15), "N/A") -> 31.558199 | T37: =IFERROR(IF(OR($F15/T15<0,$F15/T15>=100), "NM", $F15/T15), "N/A") -> 56.278839 | U37: =IFERROR(IF(OR($F15/U15<0,$F15/U15>=100), "NM", $F15/U15), "N/A") -> 52.62509 | V37: =IFERROR(IF(OR($F15/V15<0,$F15/V15>=100), "NM", $F15/V15), "N/A") -> 48.171787
B39: Maximum | F39: =MAX(F33:F37) -> 786297.78 | M39: =MAX(M33:M37) -> 836237.78 | N39: =MAX(N33:N37) -> 3.0540165 | O39: =MAX(O33:O37) -> 2.9808432 | P39: =MAX(P33:P37) -> 2.8778419 | Q39: =MAX(Q33:Q37) -> 35.683787 | R39: =MAX(R33:R37) -> 34.514009 | S39: =MAX(S33:S37) -> 31.558199 | T39: =MAX(T33:T37) -> 56.278839 | ... V39: =MAX(V33:V37) -> 48.171787
B40: 75th Percentile | F40: =_xlfn.QUARTILE.EXC(F33:F37,3) -> 606333.13 | M40: =_xlfn.QUARTILE.EXC(M33:M37,3) -> 654188.26 | N40: =_xlfn.QUARTILE.EXC(N33:N37,3) -> 2.3813068 | O40: =_xlfn.QUARTILE.EXC(O33:O37,3) -> 2.3014316 | P40: =_xlfn.QUARTILE.EXC(P33:P37,3) -> 2.1966153 | Q40: =_xlfn.QUARTILE.EXC(Q33:Q37,3) -> 27.729773 | R40: =_xlfn.QUARTILE.EXC(R33:R37,3) -> 27.135773 | S40: =_xlfn.QUARTILE.EXC(S33:S37,3) -> 24.843025 | T40: =_xlfn.QUARTILE.EXC(T33:T37,3) -> 48.120558 | ... V40: =_xlfn.QUARTILE.EXC(V33:V37,3) -> 41.961172
B41: Median | F41: =MEDIAN(F33:F37) -> 425719.74 | M41: =MEDIAN(M33:M37) -> 442193.48 | N41: =MEDIAN(N33:N37) -> 1.2410421 | O41: =MEDIAN(O33:O37) -> 1.2359046 | P41: =MEDIAN(P33:P37) -> 1.1853962 | Q41: =MEDIAN(Q33:Q37) -> 18.897644 | R41: =MEDIAN(R33:R37) -> 18.732691 | S41: =MEDIAN(S33:S37) -> 18.097928 | T41: =MEDIAN(T33:T37) -> 29.138928 | ... V41: =MEDIAN(V33:V37) -> 27.545761
B42: 25th Percentile | F42: =_xlfn.QUARTILE.EXC(F33:F37,1) -> 41952.208 | M42: =_xlfn.QUARTILE.EXC(M33:M37,1) -> 52599.708 | N42: =_xlfn.QUARTILE.EXC(N33:N37,1) -> 0.63736536 | O42: =_xlfn.QUARTILE.EXC(O33:O37,1) -> 0.64801347 | P42: =_xlfn.QUARTILE.EXC(P33:P37,1) -> 0.63409052 | Q42: =_xlfn.QUARTILE.EXC(Q33:Q37,1) -> 8.6910294 | R42: =_xlfn.QUARTILE.EXC(R33:R37,1) -> 9.0794644 | S42: =_xlfn.QUARTILE.EXC(S33:S37,1) -> 8.7072675 | T42: =_xlfn.QUARTILE.EXC(T33:T37,1) -> 14.852052 | ... V42: =_xlfn.QUARTILE.EXC(V33:V37,1) -> 14.590225
B43: Minimum | F43: =MIN(F33:F37) -> 18805.226 | M43: =MIN(M33:M37) -> 20629.226 | N43: =MIN(N33:N37) -> 0.48854322 | O43: =MIN(O33:O37) -> 0.49978743 | P43: =MIN(P33:P37) -> 0.49320358 | Q43: =MIN(Q33:Q37) -> 7.9989244 | R43: =MIN(R33:R37) -> 8.0331877 | S43: =MIN(S33:S37) -> 7.7060986 | T43: =MIN(T33:T37) -> 14.807265 | ... V43: =MIN(V33:V37) -> 13.706433
B46: Lowe's | F46: =F24 -> 157025.7 | M46: =M24 -> 193202.7 | N46: =IFERROR(IF(OR($M24/N24<0,$M24/N24>=100), "NM",$M24/N24), "N/A") -> 2.3076694 | O46: =IFERROR(IF(OR($M24/O24<0,$M24/O24>=100), "NM",$M24/O24), "N/A") -> 2.3184695 | P46: =IFERROR(IF(OR($M24/P24<0,$M24/P24>=100), "NM",$M24/P24), "N/A") -> 2.2816162 | Q46: =IFERROR(IF(OR($M24/Q24<0,$M24/Q24>=100), "NM",$M24/Q24), "N/A") -> 15.54576 | R46: =IFERROR(IF(OR($M24/R24<0,$M24/R24>=100), "NM",$M24/R24), "N/A") -> 15.875325 | S46: =IFERROR(IF(OR($M24/S24<0,$M24/S24>=100), "NM",$M24/S24), "N/A") -> 15.462401 | T46: =IFERROR(IF(OR($F24/T24<0,$F24/T24>=100), "NM",$F24/T24), "N/A") -> 22.913425 | U46: =IFERROR(IF(OR($F24/U24<0,$F24/U24>=100), "NM",$F24/U24), "N/A") -> 22.940205 | V46: =IFERROR(IF(OR($F24/V24<0,$F24/V24>=100), "NM",$F24/V24), "N/A") -> 22.358778

Sheet Multiples
B1: Lowe's (NYSE: LOW)
B2: Multiples
B5: Values in Million, Except Per Share Data | C5: 43861 | D5: 44225 | E5: 44589 | F5: 44960 | G5: 45324
C6: 2020A | D6: 2021A | E6: 2022A | F6: 2023A | G6: 2024A | H6: 2025E | I6: 2026E | J6: 2027E | K6: 2028E | L6: 2029E
B9: Enterprise Value Multiples
B10: EV/EBITDA | C10: =WACC!$F$19/DCF!C16 -> 25.246837 | D10: =WACC!$F$19/DCF!D16 -> 17.315774 | E10: =WACC!$F$19/DCF!E16 -> 13.905492 | F10: =WACC!$F$19/DCF!F16 -> 16.039416 | G10: =WACC!$F$19/DCF!G16 -> 14.409375 | H10: =WACC!$F$19/DCF!H16 -> 16.7425 | I10: =WACC!$F$19/DCF!I16 -> 16.434653 | J10: =WACC!$F$19/DCF!J16 -> 15.85157 | ... L10: =WACC!$F$19/DCF!L16 -> 14.602374
B11: EV/EBIT | C11: =WACC!$F$19/DCF!C20 -> 31.020117 | D11: =WACC!$F$19/DCF!D20 -> 20.235933 | E11: =WACC!$F$19/DCF!E20 -> 16.109664 | F11: =WACC!$F$19/DCF!F20 -> 19.234718 | G11: =WACC!$F$19/DCF!G20 -> 16.850501 | H11: =WACC!$F$19/DCF!H20 -> 19.636689 | I11: =WACC!$F$19/DCF!I20 -> 19.360479 | J11: =WACC!$F$19/DCF!J20 -> 18.684107 | ... L11: =WACC!$F$19/DCF!L20 -> 17.200854
B12: EV/Revenue | C12: =WACC!$F$19/DCF!C11 -> 2.6510789 | D12: =WACC!$F$19/DCF!D11 -> 2.1347817 | E12: =WACC!$F$19/DCF!E11 -> 1.9872212 | F12: =WACC!$F$19/DCF!F11 -> 1.9706574 | G12: =WACC!$F$19/DCF!G11 -> 2.2143631 | H12: =WACC!$F$19/DCF!H11 -> 2.27698 | I12: =WACC!$F$19/DCF!I11 -> 2.2433301 | J12: =WACC!$F$19/DCF!J11 -> 2.1716651 | ... L12: =WACC!$F$19/DCF!L11 -> 2.0078265
B13: EV/UFCF | C13: =WACC!$F$19/DCF!C31 -> 80.861393 | D13: =WACC!$F$19/DCF!D31 -> 21.674748 | E13: =WACC!$F$19/DCF!E31 -> 24.381494 | F13: =WACC!$F$19/DCF!F31 -> 43.931399 | G13: =WACC!$F$19/DCF!G31 -> 30.121499 | H13: =WACC!$F$19/DCF!H31 -> 24.804826 | I13: =WACC!$F$19/DCF!I31 -> 26.44297 | J13: =WACC!$F$19/DCF!J31 -> 25.107209 | ... L13: =WACC!$F$19/DCF!L31 -> 23.201695
B15: Equity Value Multiples
B16: P/E Ratio | C16: ='Annual Model'!C25 -> 5.49 | D16: ='Annual Model'!D25 -> 7.77 | E16: ='Annual Model'!E25 -> 12.07 | F16: ='Annual Model'!F25 -> 10.2 | G16: ='Annual Model'!G25 -> 13.23 | H16: ='Annual Model'!H25 -> 11.298176 | I16: ='Annual Model'!I25 -> 12.152846 | J16: ='Annual Model'!J25 -> 13.246388 | ... L16: ='Annual Model'!L25 -> 15.564641
B17: Price to Sales (P/S) | C17: =WACC!$F$11/DCF!C11 -> 2.1775661 | D17: =WACC!$F$11/DCF!D11 -> 1.7534855 | E17: =WACC!$F$11/DCF!E11 -> 1.6322809 | F17: =WACC!$F$11/DCF!F11 -> 1.6186756 | G17: =WACC!$F$11/DCF!G11 -> 1.8188527 | H17: =WACC!$F$11/DCF!H11 -> 1.8702855 | I17: =WACC!$F$11/DCF!I11 -> 1.8426459 | J17: =WACC!$F$11/DCF!J11 -> 1.7837811 | ... L17: =WACC!$F$11/DCF!L11 -> 1.6492059
B18: Price-to-Cash Flow (P/CF) | C18: =WACC!$F$11/'Annual Model'!C99 -> 36.57054 | D18: =WACC!$F$11/'Annual Model'!D99 -> 14.219118 | E18: =WACC!$F$11/'Annual Model'!E99 -> 15.535157 | F18: =WACC!$F$11/'Annual Model'!F99 -> 18.291657 | G18: =WACC!$F$11/'Annual Model'!G99 -> 19.300619 | H18: =WACC!$F$11/'Annual Model'!H99 -> 16.632032 | I18: =WACC!$F$11/'Annual Model'!I99 -> 17.544596 | J18: =WACC!$F$11/'Annual Model'!J99 -> 16.974856 | ... L18: =WACC!$F$11/'Annual Model'!L99 -> 15.571445
